Workbook

Sheet Cover
A1: SIDETRADE S.A. — VALUATION ANALYSIS
A2: Order-to-Cash Intelligence Platform | Euronext Growth: ALBFR.PA | FY2025 base | Valuation as of 15-Jul-2026 (v2.1)
A4: CENTRAL VALUATION — STAND-ALONE BASIS
A5: Enterprise Value — Central (DCF Base) | B5: =DCF!R34 -> 301.19453 | C5: =DCF!R34 -> 301.19453 | D5: =DCF!R34 -> 301.19453
A6: Net Debt (strict, FY25) | B6: =FY25_base!B49 -> 14.654 | C6: =FY25_base!B49 -> 14.654 | D6: =FY25_base!B49 -> 14.654
A7: Equity Value — Central | B7: =Equity_bridge!C15 -> 286.54053 | C7: =Equity_bridge!C15 -> 286.54053 | D7: =Equity_bridge!C15 -> 286.54053
A8: Diluted shares outstanding (m) | B8: =Equity_bridge!C19 -> 1.53679 | C8: =Equity_bridge!C19 -> 1.53679 | D8: =Equity_bridge!C19 -> 1.53679
A9: Implied share price (€ / share) | B9: =Equity_bridge!C20 -> 186.45392 | C9: =Equity_bridge!C20 -> 186.45392 | D9: =Equity_bridge!C20 -> 186.45392
A11: CONTROL / M&A CASE
A12: Enterprise Value — control (Transaction Comps) | B12: =Transaction_comps!F27 -> 411 | C12: ~40% control premium vs. stand-alone
A14: VALUATION RANGES SUMMARY (€m EV)
B15: Low | C15: Base / Central | D15: High | E15: Method note
A16: DCF (stand-alone) | B16: =DCF!Q34 -> 157.92189 | C16: =DCF!R34 -> 301.19453 | D16: =DCF!S34 -> 497.11514 | E16: Gordon Growth primary; linear margin
A17: Trading comps | B17: =Trading_comps!E26 -> 171 | C17: =Trading_comps!F26 -> 202 | D17: =Trading_comps!G26 -> 264 | E17: EV/Sales & EV/EBITDA 2026E peers
A18: Transaction comps | B18: =Transaction_comps!E27 -> 289 | C18: =Transaction_comps!F27 -> 411 | D18: =Transaction_comps!G27 -> 547 | E18: Includes control premium
A19: LBO affordability | B19: =LBO_full!D199 -> 222.5 | C19: =LBO_full!C199 -> 241.9 | D19: =LBO_full!B199 -> 283.5 | E19: IRR 25% / 22.5% / 18%
A21: IMPLIED MULTIPLES — CENTRAL BASE CASE
A22: EV / EBITDA FY25 (×) | B22: =DCF!R34/Inputs!B7 -> 22.504074
A23: EV / Revenue FY25 (×) | B23: =DCF!R34/Inputs!B6 -> 4.9041703
A24: EV / EBITDA 2026E (×) | B24: =DCF!R34/DCF!C12 -> 17.586714
A25: EV / Revenue 2026E (×) | B25: =DCF!R34/DCF!C7 -> 4.1915986
A27: KEY FY25 FINANCIAL METRICS (reconciled)
A28: Revenue FY25 | B28: =Inputs!B6 -> 61.416 | E28: Platform subscriptions €53.6m + Services €7.9m
A29: EBITDA FY25 (incl. CIR) | B29: =Inputs!B7 -> 13.384 | E29: GOS incl. CIR per Stat. Report p.5
A30: EBITDA margin FY25 | B30: =Inputs!B7/Inputs!B6 -> 0.21792367 | E30: 21.8%; PR rounds to 22%
A31: Subscription gross margin | B31: 0.92 | E31: 92% (stable, Stat. Report Note 3)
A32: FCF normalized FY25 | B32: =FY25_base!B56 -> 7.163 | E32: Excl. CIR timing drag of €2.947m
A33: Diluted shares | B33: =Equity_bridge!C19 -> 1.53679 | E33: 1.537m diluted (Note 30)
A35: METHODOLOGY NOTES
A36: 1. DCF: 5-year projection (2026-2030) × 3 scenarios (Bear/Base/Bull). EBITDA margin: linear interpolation FY25→2030 target. FCF = EBIT×(1−t) + D&A − Capex − ΔBFR. Mid-year discounting. Terminal Value: Gordon Growth (primary). Exit multiple cross-check (15× EBITDA).
A37: 2. CIR (Crédit Impôt Recherche): €3.5m/yr flat included in EBITDA for 2026-2030. FY25 actual: €3.482m. Risk sensitivity documented in Caveats tab.
A38: 3. Net debt: strict basis = gross financial debt €31.0m − cash+securities €16.3m = €14.7m. No adjustments for deferred revenue, earn-outs, or operating leases.
A39: 4. Trading comps: EV/Sales forward (primary) and EV/non-GAAP operating income (proxy) on refreshed peers BlackLine, BILL, nCino, Workiva — prices as of 15-Jul-2026, May-2026 guidances, EUR/USD 1.1424. Selected range fully formula-driven from the peer table.
A40: 5. Transaction comps: Esker, Coupa, Billtrust, Pagero, Bottomline. All include control premium (30-50%); not directly comparable to stand-alone DCF/trading EV.
A41: 6. LBO: full affordability model (LBO_full tab, engine-solved via lbo_engine.py): entry leverage 4.0x EBITDA FY25, all-in E3M + 479bps ≈ 7.16%, 1% mandatory amortisation + 75% cash sweep, CIR single-count, founder rollover; exit at 15× EBITDA yr 5. The earlier simplified model (35% leverage, full sweep, all-FCF-to-debt) is kept in the LBO_old tab as OBSOLETE history — do not use.
A42: 7. Margin path: point estimate = linear. Front-loaded and back-loaded paths computed in Margin_path tab. EV spread vs. linear: ±3-5%.
A43: 8. Sources: Statutory Report 31-Dec-2025 (KPMG/Yuma Audit, 21-Apr-2026), Press Release FY2025 (30-Mar-2026), O2C Intelligence 2030 Press Release (07-Apr-2026). All FY25 numbers reconciled to statutory accounts.

Sheet Inputs
A1: SIDETRADE — INPUT ASSUMPTIONS (single source of truth — all tabs point here)
A2: Blue cells = hardcoded inputs | Black cells = formulas | Green cells = cross-sheet links
A4: Parameter | B4: Bear | C4: Base | D4: Bull | E4: Notes / Source
A5: FY25 ANCHORS — reconciled against Statutory Report + Press Release FY2025
A6: Revenue FY25 (€m) | B6: 61.416 | C6: 61.416 | D6: 61.416 | E6: PR FY2025 p.1; Stat. Report Note 15 — Turnover €61,416k
A7: EBITDA FY25 incl. CIR (€m) | B7: 13.384 | C7: 13.384 | D7: 13.384 | E7: Stat. Report p.5 — Gross Operating Surplus incl. CIR: €13,384k
A8: EBIT FY25 incl. CIR (€m) | B8: 10.267 | C8: 10.267 | D8: 10.267 | E8: Stat. Report p.5 — Operating income €6,785k + CIR €3,482k = €10,267k
A9: D&A FY25 — economic proxy incl. net operating provisions (€m) | B9: 1.121 | C9: 1.121 | D9: 1.121 | E9: Stat. Report Note 19: intangible 285k + tangible 540k = 825k ≈ 1.121k incl. amort. est.
A10: Capex FY25 (€m) | B10: 1.024 | C10: 1.024 | D10: 1.024 | E10: Stat. Report Cash Flow p.6 — Acquisitions of fixed assets €1,024k
A11: EBITDA margin FY25 (computed) | B11: =B7/B6 -> 0.21792367 | C11: =C7/C6 -> 0.21792367 | D11: =D7/D6 -> 0.21792367 | E11: Matches PR: ~22% (rounded). Used as margin path anchor.
A13: REVENUE GROWTH ASSUMPTIONS (YoY, each year 2026–2030)
A14: Revenue growth 2026 | B14: 0.12 | C14: 0.17 | D14: 0.21 | E14: Q1-2026 actual: +17% reported, +21% cc, +27% subscriptions cc → Base 2026 =17% conservative
A15: Revenue growth 2027 | B15: 0.1 | C15: 0.15 | D15: 0.18
A16: Revenue growth 2028 | B16: 0.08 | C16: 0.13 | D16: 0.16
A17: Revenue growth 2029 | B17: 0.07 | C17: 0.11 | D17: 0.14 | E17: Deceleration reflects organic maturation; partially offset by AI-native bookings ramp
A18: Revenue growth 2030 | B18: 0.06 | C18: 0.09 | D18: 0.12 | E18: Bull 2030 at +12% requires AI-native >20% of bookings (O2C2030 target: >50% by 2030)
A20: EBITDA MARGIN PATH (linear interpolation — FY25 anchor → 2030 target)
A21: EBITDA margin FY25 (anchor — auto-linked) | B21: =B11 -> 0.21792367 | C21: =C11 -> 0.21792367 | D21: =D11 -> 0.21792367 | E21: Anchored to FY25 actuals via row 11. Do not override.
A22: EBITDA margin 2030 target | B22: 0.26 | C22: 0.32 | D22: 0.35 | E22: O2C Intelligence 2030 plan: 30-35% target. Bear < low end; Base = mid; Bull = top.
A23: Implied EBITDA margin 2026 | B23: =B21+(B22-B21)*1/5 -> 0.22633893 | C23: =C21+(C22-C21)*1/5 -> 0.23833893 | D23: =D21+(D22-D21)*1/5 -> 0.24433893 | E23: Linear interp: margin_t = anchor + (target − anchor) × t/5. Year 1=2026, year 5=2030.
A24: Implied EBITDA margin 2027 | B24: =B21+(B22-B21)*2/5 -> 0.2347542 | C24: =C21+(C22-C21)*2/5 -> 0.2587542 | D24: =D21+(D22-D21)*2/5 -> 0.2707542
A25: Implied EBITDA margin 2028 | B25: =B21+(B22-B21)*3/5 -> 0.24316947 | C25: =C21+(C22-C21)*3/5 -> 0.27916947 | D25: =D21+(D22-D21)*3/5 -> 0.29716947
A26: Implied EBITDA margin 2029 | B26: =B21+(B22-B21)*4/5 -> 0.25158473 | C26: =C21+(C22-C21)*4/5 -> 0.29958473 | D26: =D21+(D22-D21)*4/5 -> 0.32358473
A27: Implied EBITDA margin 2030 | B27: =B21+(B22-B21)*5/5 -> 0.26 | C27: =C21+(C22-C21)*5/5 -> 0.32 | D27: =D21+(D22-D21)*5/5 -> 0.35
A29: P&L & CASH FLOW DRIVERS
A30: D&A / Revenue (cash D&A, excl. goodwill & provisions) | B30: 0.02 | C30: 0.02 | D30: 0.02 | E30: FY25 actual: 1.121/61.4=1.8% → rounded to 2.0%. Stable; GPU capex adds to D&A from 2027.
A31: Effective tax rate (cash taxes / EBIT) | B31: 0.25 | C31: 0.22 | D31: 0.2 | E31: FY25 cash tax ~€1.2m on EBIT €10.3m = 11.7% (depressed by tax losses). Forward: CIR effect fades.
A32: Capex / Revenue | B32: 0.03 | C32: 0.027 | D32: 0.025 | E32: FY25 actual: 1.7%. Bear elevated for GPU ramp (O2C2030 plan: ~€4.1m cumulative GPU capex over 5yr).
A33: ΔBFR / ΔRevenue (working capital intensity) | B33: 0.1 | C33: 0.07 | D33: 0.05 | E33: FY25 normalized: ~7% of ΔRev (ex-CIR timing). Bear higher for slower collections on new clients.
A34: CIR (Crédit Impôt Recherche) — annual flat included in EBITDA (€m) | B34: 3.5 | C34: 3.5 | D34: 3.5 | E34: FY25: €3.482m. Flat assumption per management R&D investment trajectory. *** See Caveats tab ***
A36: VALUATION PARAMETERS
A37: WACC | B37: 0.105 | C37: 0.095 | D37: 0.085 | E37: SaaS small-cap France. Rf ~3.5%, ERP ~6%, levered beta 1.1-1.3, +size prem. Bear: higher risk prem.
A38: Terminal growth rate | B38: 0.02 | C38: 0.025 | D38: 0.03 | E38: Long-run O2C market + inflation. Below 3% EUR nominal GDP. Cross-check: WACC must > TG.
A39: Terminal Value exit multiple (×EBITDA) — cross-check only | B39: 15 | C39: 15 | D39: 15 | E39: Conservative vs trading comps (24-35×). Used for TV cross-check; Gordon Growth is PRIMARY method.
A41: LBO PARAMETERS
A42: Entry leverage (Debt / Entry EV) | B42: 0.35 | C42: =B42 -> 0.35 | D42: =B42 -> 0.35 | E42: Conservative for small-cap tech (typical PE: 35-50%). Same across scenarios.
A43: LBO exit multiple (×EBITDA) | B43: 15 | C43: =B43 -> 15 | D43: =B43 -> 15 | E43: Aligned with TV cross-check (row 39).
A45: WACC BUILD — bridge reproductible (Base) — ajouté 15/07/2026 (audit §4.3)
A46: Taux sans risque (OAT 10 ans) | C46: 0.035 | E46: Niveau retenu dans le modèle ; re-vérifier sur Banque de France / BCE à la date de publication
A47: Prime de risque actions zone euro (ERP) | C47: 0.055 | E47: Kroll — Recommended Eurozone ERP (kroll.com/en/reports/cost-of-capital) ; re-vérifier à date
...

Sheet FY25_base
A1: FY25 BASE — FULL RECONCILIATION (sources: Statutory Report 31-Dec-2025 + Press Release 30-Mar-2026)
A3: P&L RECONCILIATION (€k) | C3: FY2025 | D3: FY2024
A4: Turnover (Revenue) | B4: 61416 | C4: 54977 | D4: Note 15 / PR p.1
A5: Platform subscriptions | B5: 53594 | C5: 45467 | D5: Note 15
A6: Services | B6: 7904 | C6: 9510 | D6: Note 15
A7: Other operational revenue | B7: 4048 | C7: 2942 | D7: Note 16: CIR rebill + provisions reversals + email services
A8: Purchases consumed | B8: -15280 | C8: -13219 | D8: P&L statement
A9: Payroll costs | B9: -38170 | C9: -35252 | D9: Note 17
A10: Other operating expenses | B10: -876 | C10: -298 | D10: P&L statement
A11: Taxes | B11: -425 | C11: -412 | D11: Note 18
A12: D&A & provisions (excl. goodwill) | B12: -3633 | C12: -2710 | D12: Note 19 — all allocations excl. goodwill
A13: Operating income — statutory (EBIT pre-CIR) | B13: =B4+B7+B8+B9+B10+B11+B12 -> 7080 | C13: =C4+C7+C8+C9+C10+C11+C12 -> 6028 | D13: = €6,785k (2025); matches Stat. Report p.4 'Operating income before dep.' then less goodwill
A14: Goodwill amortization | B14: -296 | C14: -221 | D14: Note 19 — depreciation on customer relations
A15: EBIT statutory (pre-CIR) | B15: =B13+B14 -> 6784 | C15: =C13+C14 -> 5807
A16: + CIR reclassified (from income tax line) | B16: 3482 | C16: 2560 | D16: Note 3 / Note 22 — CIR €3,482k reclassified as operating income per ANC reg.
A17: EBIT incl. CIR (€k) | B17: =B15+B16 -> 10266 | C17: =C15+C16 -> 8367 | D17: = €10,267k (2025); PR rounds to €10.3m ✓ Inputs!B8 = 10.267
A19: EBITDA (EBE) RECONCILIATION per Stat. Report Note 3 / p.5 (€k) | C19: FY2025 | D19: FY2024
A20: EBIT incl. CIR (from row 17) | B20: =B17 -> 10266 | C20: =C17 -> 8367
A21: + All D&A & provisions (excl. goodwill) | B21: 3929 | C21: 2931 | D21: Note 19 total 'operational allocations' = 3,929k
A22: – Reversal of operating provisions | B22: -812 | C22: -321 | D22: Note 16: reversal of operating provisions €812k (2025)
A23: Gross Operating Surplus (EBITDA) incl. CIR (€k) | B23: =B20+B21+B22 -> 13383 | C23: =C20+C21+C22 -> 10977 | D23: = €13,384k ✓ matches Stat. Report p.5 and PR '€13.4m EBITDA'
A24: EBITDA margin | B24: =B23/B4 -> 0.21790739 | C24: =C23/C4 -> 0.19966531 | D24: = 21.8% (2025) / 20.0% (2024). PR states '22%' (rounded). Inputs!B7 uses 21.8%
A26: D&A DECOMPOSITION — cash vs. non-cash (€k, FY2025) | C26: €k
A27: Intangible D&A (dev costs 227k + concessions 39k) | B27: 266 | D27: Note 19
A28: Customer relations amortization | B28: 296 | D28: Note 19
A29: Tangible D&A (facilities 175k + other 400k) | B29: 575 | D29: Note 19
A30: Goodwill amortization | B30: 296 | D30: Note 19 (not in FCF D&A)
A31: Cash D&A total (rows 27+29, excl. goodwill & cust. relations) | B31: =B27+B29 -> 841 | D31: = 841k ≈ 1.4% Rev. Inputs uses 2.0% which adds operating provisions for forward est.
A32: + Operating provisions (net of reversals) | B32: 280 | D32: Note 19: provisions 609k+34k retirement – 321k reversals ≈ 280k net non-cash
A33: Total D&A proxy for forward D&A (Inputs!B9 × 1000) | B33: =B31+B32 -> 1121 | D33: = ~1,121k = 1.8% of revenue → rounded to 2.0% in forward projection (Inputs row 30)
A35: BALANCE SHEET — KEY ITEMS (€k, 31-Dec) | C35: 2025 | D35: 2024
A36: Total assets | B36: 112987 | C36: 76705 | D36: Stat. Report Consolidated Balance Sheet p.3
A37: Intangible fixed assets (incl. goodwill) | B37: 69194 | C37: 30776
A38: Tangible fixed assets | B38: 831 | C38: 957
A39: Customer receivables (net) | B39: 11926 | C39: 9835
A40: Cash | B40: 5402 | C40: 12691
A41: Marketable securities | B41: 10925 | C41: 12534
A42: Total equity (group share) | B42: 50183 | C42: 39404
A43: Financial debt (loans) | B43: 30981 | C43: 7912 | D43: BNP €10m + LCL €15m (ezyCollect acq.) + BNP/BPI legacy €5.8m = €30.8m ~ 31.0m
A45: NET DEBT BRIDGE (€m) | C45: €m
...

Sheet DCF
A1: DCF PROJECTION — SIDETRADE FY2026–2030 (€m)
A2: FCF formula: NOPAT + D&A – Capex – ΔBFR | Mid-year discounting: PV = FCF/(1+WACC)^(t–0.5) | TV: Gordon Growth (primary) + Exit Multiple (cross-check)
B3: 2026 | E3: 2027 | H3: 2028 | K3: 2029 | N3: 2030 | Q3: VALUATION SUMMARY
B4: Bear | C4: Base | D4: Bull | E4: Bear | F4: Base | G4: Bull | H4: Bear | I4: Base | J4: Bull | K4: Bear | L4: Base | M4: Bull | N4: Bear | O4: Base | P4: Bull | Q4: Bear EV | R4: Base EV | S4: Bull EV
A6: REVENUE
A7: Revenue (€m) | B7: =Inputs!B6*(1+Inputs!B14) -> 68.78592 | C7: =Inputs!C6*(1+Inputs!C14) -> 71.85672 | D7: =Inputs!D6*(1+Inputs!D14) -> 74.31336 | E7: =B7*(1+Inputs!B15) -> 75.664512 | F7: =C7*(1+Inputs!C15) -> 82.635228 | G7: =D7*(1+Inputs!D15) -> 87.689765 | H7: =E7*(1+Inputs!B16) -> 81.717673 | I7: =F7*(1+Inputs!C16) -> 93.377808 | J7: =G7*(1+Inputs!D16) -> 101.72013 | K7: =H7*(1+Inputs!B17) -> 87.43791 | L7: =I7*(1+Inputs!C17) -> 103.64937 | M7: =J7*(1+Inputs!D17) -> 115.96094 | N7: =K7*(1+Inputs!B18) -> 92.684185 | O7: =L7*(1+Inputs!C18) -> 112.97781 | P7: =M7*(1+Inputs!D18) -> 129.87626
A8: YoY growth % | B8: =Inputs!B14 -> 0.12 | C8: =Inputs!C14 -> 0.17 | D8: =Inputs!D14 -> 0.21 | E8: =Inputs!B15 -> 0.1 | F8: =Inputs!C15 -> 0.15 | G8: =Inputs!D15 -> 0.18 | H8: =Inputs!B16 -> 0.08 | I8: =Inputs!C16 -> 0.13 | J8: =Inputs!D16 -> 0.16 | K8: =Inputs!B17 -> 0.07 | L8: =Inputs!C17 -> 0.11 | M8: =Inputs!D17 -> 0.14 | N8: =Inputs!B18 -> 0.06 | O8: =Inputs!C18 -> 0.09 | P8: =Inputs!D18 -> 0.12
A10: PROFITABILITY
A11: EBITDA margin | B11: =Inputs!B23 -> 0.22633893 | C11: =Inputs!C23 -> 0.23833893 | D11: =Inputs!D23 -> 0.24433893 | E11: =Inputs!B24 -> 0.2347542 | F11: =Inputs!C24 -> 0.2587542 | G11: =Inputs!D24 -> 0.2707542 | H11: =Inputs!B25 -> 0.24316947 | I11: =Inputs!C25 -> 0.27916947 | J11: =Inputs!D25 -> 0.29716947 | K11: =Inputs!B26 -> 0.25158473 | L11: =Inputs!C26 -> 0.29958473 | M11: =Inputs!D26 -> 0.32358473 | N11: =Inputs!B27 -> 0.26 | O11: =Inputs!C27 -> 0.32 | P11: =Inputs!D27 -> 0.35
A12: EBITDA (€m) | B12: =B7*B11 -> 15.568932 | C12: =C7*C11 -> 17.126254 | D12: =D7*D11 -> 18.157647 | E12: =E7*E11 -> 17.762562 | F12: =F7*F11 -> 21.382212 | G12: =G7*G11 -> 23.742372 | H12: =H7*H11 -> 19.871243 | I12: =I7*I11 -> 26.068233 | ... P12: =P7*P11 -> 45.45669
A13: D&A (€m) | B13: =B7*Inputs!B30 -> 1.3757184 | C13: =C7*Inputs!C30 -> 1.4371344 | D13: =D7*Inputs!D30 -> 1.4862672 | E13: =E7*Inputs!B30 -> 1.5132902 | F13: =F7*Inputs!C30 -> 1.6527046 | G13: =G7*Inputs!D30 -> 1.7537953 | H13: =H7*Inputs!B30 -> 1.6343535 | I13: =I7*Inputs!C30 -> 1.8675562 | J13: =J7*Inputs!D30 -> 2.0344025 | K13: =K7*Inputs!B30 -> 1.7487582 | L13: =L7*Inputs!C30 -> 2.0729873 | M13: =M7*Inputs!D30 -> 2.3192189 | N13: =N7*Inputs!B30 -> 1.8536837 | O13: =O7*Inputs!C30 -> 2.2595562 | P13: =P7*Inputs!D30 -> 2.5975252
A14: EBIT (€m) | B14: =B12-B13 -> 14.193213 | C14: =C12-C13 -> 15.68912 | D14: =D12-D13 -> 16.67138 | E14: =E12-E13 -> 16.249272 | F14: =F12-F13 -> 19.729508 | G14: =G12-G13 -> 21.988577 | H14: =H12-H13 -> 18.23689 | I14: =I12-I13 -> 24.200677 | ... P14: =P12-P13 -> 42.859165
A16: FREE CASH FLOW
A17: Cash taxes (EBIT × t) | B17: =B14*Inputs!B31 -> 3.5483034 | C17: =C14*Inputs!C31 -> 3.4516063 | D17: =D14*Inputs!D31 -> 3.334276 | E17: =E14*Inputs!B31 -> 4.062318 | F17: =F14*Inputs!C31 -> 4.3404917 | G17: =G14*Inputs!D31 -> 4.3977154 | H17: =H14*Inputs!B31 -> 4.5592224 | I17: =I14*Inputs!C31 -> 5.3241489 | J17: =J14*Inputs!D31 -> 5.6387427 | K17: =K14*Inputs!B31 -> 5.0623213 | L17: =L14*Inputs!C31 -> 6.3753317 | M17: =M14*Inputs!D31 -> 7.0407945 | N17: =N14*Inputs!B31 -> 5.5610511 | O17: =O14*Inputs!C31 -> 7.4565354 | P17: =P14*Inputs!D31 -> 8.5718331
A18: NOPAT = EBIT × (1–t) | B18: =B14*(1-Inputs!B31) -> 10.64491 | C18: =C14*(1-Inputs!C31) -> 12.237513 | D18: =D14*(1-Inputs!D31) -> 13.337104 | E18: =E14*(1-Inputs!B31) -> 12.186954 | F18: =F14*(1-Inputs!C31) -> 15.389016 | G18: =G14*(1-Inputs!D31) -> 17.590862 | H18: =H14*(1-Inputs!B31) -> 13.677667 | I18: =I14*(1-Inputs!C31) -> 18.876528 | J18: =J14*(1-Inputs!D31) -> 22.554971 | K18: =K14*(1-Inputs!B31) -> 15.186964 | L18: =L14*(1-Inputs!C31) -> 22.603449 | M18: =M14*(1-Inputs!D31) -> 28.163178 | N18: =N14*(1-Inputs!B31) -> 16.683153 | O18: =O14*(1-Inputs!C31) -> 26.436807 | P18: =P14*(1-Inputs!D31) -> 34.287332
A19: Capex (–) | B19: =-B7*Inputs!B32 -> -2.0635776 | C19: =-C7*Inputs!C32 -> -1.9401314 | D19: =-D7*Inputs!D32 -> -1.857834 | E19: =-E7*Inputs!B32 -> -2.2699354 | F19: =-F7*Inputs!C32 -> -2.2311512 | G19: =-G7*Inputs!D32 -> -2.1922441 | H19: =-H7*Inputs!B32 -> -2.4515302 | I19: =-I7*Inputs!C32 -> -2.5212008 | J19: =-J7*Inputs!D32 -> -2.5430032 | K19: =-K7*Inputs!B32 -> -2.6231373 | L19: =-L7*Inputs!C32 -> -2.7985329 | M19: =-M7*Inputs!D32 -> -2.8990236 | N19: =-N7*Inputs!B32 -> -2.7805255 | O19: =-O7*Inputs!C32 -> -3.0504009 | P19: =-P7*Inputs!D32 -> -3.2469065
A20: ΔBFR (–) | B20: =-(B7-Inputs!B6)*Inputs!B33 -> -0.736992 | C20: =-(C7-Inputs!C6)*Inputs!C33 -> -0.7308504 | D20: =-(D7-Inputs!D6)*Inputs!D33 -> -0.644868 | E20: =-(E7-B7)*Inputs!B33 -> -0.6878592 | F20: =-(F7-C7)*Inputs!C33 -> -0.75449556 | G20: =-(G7-D7)*Inputs!D33 -> -0.66882024 | H20: =-(H7-E7)*Inputs!B33 -> -0.6053161 | I20: =-(I7-F7)*Inputs!C33 -> -0.75198057 | J20: =-(J7-G7)*Inputs!D33 -> -0.70151812 | K20: =-(K7-H7)*Inputs!B33 -> -0.57202371 | L20: =-(L7-I7)*Inputs!C33 -> -0.71900912 | M20: =-(M7-J7)*Inputs!D33 -> -0.71204089 | N20: =-(N7-K7)*Inputs!B33 -> -0.52462746 | O20: =-(O7-L7)*Inputs!C33 -> -0.65299101 | P20: =-(P7-M7)*Inputs!D33 -> -0.69576567
A21: Unlevered FCF M1: NOPAT + D&A – Capex – ΔBFR (€m) | B21: =B18+B13+B19+B20 -> 9.2200589 | C21: =C18+C13+C19+C20 -> 11.003666 | D21: =D18+D13+D19+D20 -> 12.320669 | E21: =E18+E13+E19+E20 -> 10.74245 | F21: =F18+F13+F19+F20 -> 14.056074 | G21: =G18+G13+G19+G20 -> 16.483592 | H21: =H18+H13+H19+H20 -> 12.255174 | I21: =I18+I13+I19+I20 -> 17.470903 | ... P21: =P18+P13+P19+P20 -> 32.942185
A22: FCF cross-check M2: EBITDA – CashTax – Capex – ΔBFR (€m) | B22: =B12-B17+B19+B20 -> 9.2200589 | C22: =C12-C17+C19+C20 -> 11.003666 | D22: =D12-D17+D19+D20 -> 12.320669 | E22: =E12-E17+E19+E20 -> 10.74245 | F22: =F12-F17+F19+F20 -> 14.056074 | G22: =G12-G17+G19+G20 -> 16.483592 | H22: =H12-H17+H19+H20 -> 12.255174 | I22: =I12-I17+I19+I20 -> 17.470903 | ... P22: =P12-P17+P19+P20 -> 32.942185
A24: DISCOUNTING (mid-year convention: PV = FCF/(1+WACC)^(t–0.5))
A25: Discount period t–0.5 | B25: 0.5 | C25: 0.5 | D25: 0.5 | E25: 1.5 | F25: 1.5 | G25: 1.5 | H25: 2.5 | I25: 2.5 | J25: 2.5 | K25: 3.5 | L25: 3.5 | M25: 3.5 | N25: 4.5 | O25: 4.5 | P25: 4.5
A26: Discount factor 1/(1+WACC)^(t–0.5) | B26: =1/(1+Inputs!B37)^0.5 -> 0.95130299 | C26: =1/(1+Inputs!C37)^0.5 -> 0.95563697 | D26: =1/(1+Inputs!D37)^0.5 -> 0.96003072 | E26: =1/(1+Inputs!B37)^1.5 -> 0.86090768 | F26: =1/(1+Inputs!C37)^1.5 -> 0.87272782 | G26: =1/(1+Inputs!D37)^1.5 -> 0.88482094 | H26: =1/(1+Inputs!B37)^2.5 -> 0.77910197 | I26: =1/(1+Inputs!C37)^2.5 -> 0.79701171 | J26: =1/(1+Inputs!D37)^2.5 -> 0.81550317 | K26: =1/(1+Inputs!B37)^3.5 -> 0.70506966 | L26: =1/(1+Inputs!C37)^3.5 -> 0.72786458 | M26: =1/(1+Inputs!D37)^3.5 -> 0.75161583 | N26: =1/(1+Inputs!B37)^4.5 -> 0.63807209 | O26: =1/(1+Inputs!C37)^4.5 -> 0.66471651 | P26: =1/(1+Inputs!D37)^4.5 -> 0.69273348
A27: PV(FCF) (€m) | B27: =B21*B26 -> 8.7710696 | C27: =C21*C26 -> 10.51551 | D27: =D21*D26 -> 11.828221 | E27: =E21*E26 -> 9.2482573 | F27: =F21*F26 -> 12.267127 | G27: =G21*G26 -> 14.585028 | H27: =H21*H26 -> 9.5480305 | I27: =I21*I26 -> 13.924514 | ... P27: =P21*P26 -> 22.820155
A29: VALUATION SUMMARY (€m) | Q29: Bear | R29: Base | S29: Bull
A30: Sum PV(FCF) — discounted projection period | Q30: =B27+E27+H27+K27+N27 -> 46.974323 | R30: =C27+F27+I27+L27+O27 -> 68.721201 | S30: =D27+G27+J27+M27+P27 -> 86.837117
A31: Terminal FCF = FCF₂₀₃₀ × (1+g) | Q31: =N21*(1+Inputs!B38) -> 15.536318 | R31: =O21*(1+Inputs!C38) -> 25.617796 | S31: =P21*(1+Inputs!D38) -> 33.930451
A32: Terminal Value — Gordon Growth TV = FCF₂₀₃₀×(1+g) / (WACC–g) | Q32: =Q31/(Inputs!B37-Inputs!B38) -> 182.78021 | R32: =R31/(Inputs!C37-Inputs!C38) -> 365.96851 | S32: =S31/(Inputs!D37-Inputs!D38) -> 616.91729
A33: PV(Terminal Value) = TV / (1+WACC)^5 | Q33: =Q32/(1+Inputs!B37)^5 -> 110.94757 | R33: =R32/(1+Inputs!C37)^5 -> 232.47333 | S33: =S32/(1+Inputs!D37)^5 -> 410.27802
A34: Enterprise Value [Gordon — PRIMARY] (€m) | Q34: =Q30+Q33 -> 157.92189 | R34: =R30+R33 -> 301.19453 | S34: =S30+S33 -> 497.11514
A36: Terminal Value — exit multiple cross-check = EBITDA₂₀₃₀ × mult. | Q36: =N12*Inputs!B39 -> 361.46832 | R36: =O12*Inputs!C39 -> 542.29349 | S36: =P12*Inputs!D39 -> 681.85036
A37: PV(TV — exit multiple) | Q37: =Q36/(1+Inputs!B37)^5 -> 219.41123 | R37: =R36/(1+Inputs!C37)^5 -> 344.47982 | S37: =S36/(1+Inputs!D37)^5 -> 453.46146
A38: EV [exit multiple cross-check] (€m) | Q38: =Q30+Q37 -> 266.38555 | R38: =R30+R37 -> 413.20103 | S38: =S30+S37 -> 540.29858
A40: Implied exit EBITDA multiple from Gordon TV (×) | Q40: =Q32/N12 -> 7.5849057 | R40: =R32/O12 -> 10.122799 | S40: =S32/P12 -> 13.57154
A41: TV as % of total EV (TV/EV) | Q41: =Q33/Q34 -> 0.70254711 | R41: =R33/R34 -> 0.77183782 | S41: =S33/S34 -> 0.8253179
A42: Implied EV / EBITDA FY25 (×) | Q42: =Q34/Inputs!B7 -> 11.799304 | R42: =R34/Inputs!B7 -> 22.504074 | S42: =S34/Inputs!B7 -> 37.142494
A43: Implied EV / Revenue FY25 (×) | Q43: =Q34/Inputs!B6 -> 2.5713477 | R43: =R34/Inputs!B6 -> 4.9041703 | S43: =S34/Inputs!B6 -> 8.0942285

Sheet Sensitivity
A1: SENSITIVITY — BASE CASE EV (€m) | FCFs from DCF Base columns (C, F, I, L, O)
A2: PV recomputed with sensitivity WACC & TG/multiple. Base FCFs fixed at DCF Base scenario rows 21 (year FCFs).
A4: TABLE 1 — EV (€m) : WACC (rows) × Terminal Growth Rate (cols)
A5: WACC ↓ \ TG → | C5: 0.015 | D5: 0.02 | E5: 0.025 | F5: 0.03 | G5: 0.035
B6: 0.075 | C6: =DCF!C21/(1+$B6)^0.5+DCF!F21/(1+$B6)^1.5+DCF!I21/(1+$B6)^2.5+DCF!L21/(1+$B6)^3.5+DCF!O21/(1+$B6)^4.5+(DCF!O21*(1+0.015)/($B6-0.015))/(1+$B6)^5 -> 366.7859 | D6: =DCF!C21/(1+$B6)^0.5+DCF!F21/(1+$B6)^1.5+DCF!I21/(1+$B6)^2.5+DCF!L21/(1+$B6)^3.5+DCF!O21/(1+$B6)^4.5+(DCF!O21*(1+0.02)/($B6-0.02))/(1+$B6)^5 -> 395.14158 | E6: =DCF!C21/(1+$B6)^0.5+DCF!F21/(1+$B6)^1.5+DCF!I21/(1+$B6)^2.5+DCF!L21/(1+$B6)^3.5+DCF!O21/(1+$B6)^4.5+(DCF!O21*(1+0.025)/($B6-0.025))/(1+$B6)^5 -> 429.1684 | F6: =DCF!C21/(1+$B6)^0.5+DCF!F21/(1+$B6)^1.5+DCF!I21/(1+$B6)^2.5+DCF!L21/(1+$B6)^3.5+DCF!O21/(1+$B6)^4.5+(DCF!O21*(1+0.03)/($B6-0.03))/(1+$B6)^5 -> 470.75674 | G6: =DCF!C21/(1+$B6)^0.5+DCF!F21/(1+$B6)^1.5+DCF!I21/(1+$B6)^2.5+DCF!L21/(1+$B6)^3.5+DCF!O21/(1+$B6)^4.5+(DCF!O21*(1+0.035)/($B6-0.035))/(1+$B6)^5 -> 522.74215
B7: 0.085 | C7: =DCF!C21/(1+$B7)^0.5+DCF!F21/(1+$B7)^1.5+DCF!I21/(1+$B7)^2.5+DCF!L21/(1+$B7)^3.5+DCF!O21/(1+$B7)^4.5+(DCF!O21*(1+0.015)/($B7-0.015))/(1+$B7)^5 -> 311.47656 | D7: =DCF!C21/(1+$B7)^0.5+DCF!F21/(1+$B7)^1.5+DCF!I21/(1+$B7)^2.5+DCF!L21/(1+$B7)^3.5+DCF!O21/(1+$B7)^4.5+(DCF!O21*(1+0.02)/($B7-0.02))/(1+$B7)^5 -> 331.29446 | E7: =DCF!C21/(1+$B7)^0.5+DCF!F21/(1+$B7)^1.5+DCF!I21/(1+$B7)^2.5+DCF!L21/(1+$B7)^3.5+DCF!O21/(1+$B7)^4.5+(DCF!O21*(1+0.025)/($B7-0.025))/(1+$B7)^5 -> 354.41534 | F7: =DCF!C21/(1+$B7)^0.5+DCF!F21/(1+$B7)^1.5+DCF!I21/(1+$B7)^2.5+DCF!L21/(1+$B7)^3.5+DCF!O21/(1+$B7)^4.5+(DCF!O21*(1+0.03)/($B7-0.03))/(1+$B7)^5 -> 381.74001 | G7: =DCF!C21/(1+$B7)^0.5+DCF!F21/(1+$B7)^1.5+DCF!I21/(1+$B7)^2.5+DCF!L21/(1+$B7)^3.5+DCF!O21/(1+$B7)^4.5+(DCF!O21*(1+0.035)/($B7-0.035))/(1+$B7)^5 -> 414.52962
B8: 0.095 | C8: =DCF!C21/(1+$B8)^0.5+DCF!F21/(1+$B8)^1.5+DCF!I21/(1+$B8)^2.5+DCF!L21/(1+$B8)^3.5+DCF!O21/(1+$B8)^4.5+(DCF!O21*(1+0.015)/($B8-0.015))/(1+$B8)^5 -> 270.15083 | D8: =DCF!C21/(1+$B8)^0.5+DCF!F21/(1+$B8)^1.5+DCF!I21/(1+$B8)^2.5+DCF!L21/(1+$B8)^3.5+DCF!O21/(1+$B8)^4.5+(DCF!O21*(1+0.02)/($B8-0.02))/(1+$B8)^5 -> 284.63789 | E8: =DCF!C21/(1+$B8)^0.5+DCF!F21/(1+$B8)^1.5+DCF!I21/(1+$B8)^2.5+DCF!L21/(1+$B8)^3.5+DCF!O21/(1+$B8)^4.5+(DCF!O21*(1+0.025)/($B8-0.025))/(1+$B8)^5 -> 301.19453 | F8: =DCF!C21/(1+$B8)^0.5+DCF!F21/(1+$B8)^1.5+DCF!I21/(1+$B8)^2.5+DCF!L21/(1+$B8)^3.5+DCF!O21/(1+$B8)^4.5+(DCF!O21*(1+0.03)/($B8-0.03))/(1+$B8)^5 -> 320.29834 | G8: =DCF!C21/(1+$B8)^0.5+DCF!F21/(1+$B8)^1.5+DCF!I21/(1+$B8)^2.5+DCF!L21/(1+$B8)^3.5+DCF!O21/(1+$B8)^4.5+(DCF!O21*(1+0.035)/($B8-0.035))/(1+$B8)^5 -> 342.58612
B9: 0.105 | C9: =DCF!C21/(1+$B9)^0.5+DCF!F21/(1+$B9)^1.5+DCF!I21/(1+$B9)^2.5+DCF!L21/(1+$B9)^3.5+DCF!O21/(1+$B9)^4.5+(DCF!O21*(1+0.015)/($B9-0.015))/(1+$B9)^5 -> 238.13836 | D9: =DCF!C21/(1+$B9)^0.5+DCF!F21/(1+$B9)^1.5+DCF!I21/(1+$B9)^2.5+DCF!L21/(1+$B9)^3.5+DCF!O21/(1+$B9)^4.5+(DCF!O21*(1+0.02)/($B9-0.02))/(1+$B9)^5 -> 249.095 | E9: =DCF!C21/(1+$B9)^0.5+DCF!F21/(1+$B9)^1.5+DCF!I21/(1+$B9)^2.5+DCF!L21/(1+$B9)^3.5+DCF!O21/(1+$B9)^4.5+(DCF!O21*(1+0.025)/($B9-0.025))/(1+$B9)^5 -> 261.42122 | F9: =DCF!C21/(1+$B9)^0.5+DCF!F21/(1+$B9)^1.5+DCF!I21/(1+$B9)^2.5+DCF!L21/(1+$B9)^3.5+DCF!O21/(1+$B9)^4.5+(DCF!O21*(1+0.03)/($B9-0.03))/(1+$B9)^5 -> 275.39093 | G9: =DCF!C21/(1+$B9)^0.5+DCF!F21/(1+$B9)^1.5+DCF!I21/(1+$B9)^2.5+DCF!L21/(1+$B9)^3.5+DCF!O21/(1+$B9)^4.5+(DCF!O21*(1+0.035)/($B9-0.035))/(1+$B9)^5 -> 291.35632
B10: 0.115 | C10: =DCF!C21/(1+$B10)^0.5+DCF!F21/(1+$B10)^1.5+DCF!I21/(1+$B10)^2.5+DCF!L21/(1+$B10)^3.5+DCF!O21/(1+$B10)^4.5+(DCF!O21*(1+0.015)/($B10-0.015))/(1+$B10)^5 -> 212.63756 | D10: =DCF!C21/(1+$B10)^0.5+DCF!F21/(1+$B10)^1.5+DCF!I21/(1+$B10)^2.5+DCF!L21/(1+$B10)^3.5+DCF!O21/(1+$B10)^4.5+(DCF!O21*(1+0.02)/($B10-0.02))/(1+$B10)^5 -> 221.14826 | E10: =DCF!C21/(1+$B10)^0.5+DCF!F21/(1+$B10)^1.5+DCF!I21/(1+$B10)^2.5+DCF!L21/(1+$B10)^3.5+DCF!O21/(1+$B10)^4.5+(DCF!O21*(1+0.025)/($B10-0.025))/(1+$B10)^5 -> 230.60458 | F10: =DCF!C21/(1+$B10)^0.5+DCF!F21/(1+$B10)^1.5+DCF!I21/(1+$B10)^2.5+DCF!L21/(1+$B10)^3.5+DCF!O21/(1+$B10)^4.5+(DCF!O21*(1+0.03)/($B10-0.03))/(1+$B10)^5 -> 241.17341 | G10: =DCF!C21/(1+$B10)^0.5+DCF!F21/(1+$B10)^1.5+DCF!I21/(1+$B10)^2.5+DCF!L21/(1+$B10)^3.5+DCF!O21/(1+$B10)^4.5+(DCF!O21*(1+0.035)/($B10-0.035))/(1+$B10)^5 -> 253.06335
A12: Highlighted cell = Base case (WACC 9.5%, TG 2.5%)
A14: TABLE 2 — EV (€m) : WACC (rows) × EBITDA Exit Multiple (cols)
A15: WACC ↓ \ Exit Mult → | C15: 10 | D15: 12.5 | E15: 15 | F15: 17.5 | G15: 20
B16: 0.075 | C16: =DCF!C21/(1+$B16)^0.5+DCF!F21/(1+$B16)^1.5+DCF!I21/(1+$B16)^2.5+DCF!L21/(1+$B16)^3.5+DCF!O21/(1+$B16)^4.5+(DCF!O12*10)/(1+$B16)^5 -> 324.1086 | D16: =DCF!C21/(1+$B16)^0.5+DCF!F21/(1+$B16)^1.5+DCF!I21/(1+$B16)^2.5+DCF!L21/(1+$B16)^3.5+DCF!O21/(1+$B16)^4.5+(DCF!O12*12.5)/(1+$B16)^5 -> 387.06514 | E16: =DCF!C21/(1+$B16)^0.5+DCF!F21/(1+$B16)^1.5+DCF!I21/(1+$B16)^2.5+DCF!L21/(1+$B16)^3.5+DCF!O21/(1+$B16)^4.5+(DCF!O12*15)/(1+$B16)^5 -> 450.02167 | F16: =DCF!C21/(1+$B16)^0.5+DCF!F21/(1+$B16)^1.5+DCF!I21/(1+$B16)^2.5+DCF!L21/(1+$B16)^3.5+DCF!O21/(1+$B16)^4.5+(DCF!O12*17.5)/(1+$B16)^5 -> 512.9782 | G16: =DCF!C21/(1+$B16)^0.5+DCF!F21/(1+$B16)^1.5+DCF!I21/(1+$B16)^2.5+DCF!L21/(1+$B16)^3.5+DCF!O21/(1+$B16)^4.5+(DCF!O12*20)/(1+$B16)^5 -> 575.93474
B17: 0.085 | C17: =DCF!C21/(1+$B17)^0.5+DCF!F21/(1+$B17)^1.5+DCF!I21/(1+$B17)^2.5+DCF!L21/(1+$B17)^3.5+DCF!O21/(1+$B17)^4.5+(DCF!O12*10)/(1+$B17)^5 -> 310.89857 | D17: =DCF!C21/(1+$B17)^0.5+DCF!F21/(1+$B17)^1.5+DCF!I21/(1+$B17)^2.5+DCF!L21/(1+$B17)^3.5+DCF!O21/(1+$B17)^4.5+(DCF!O12*12.5)/(1+$B17)^5 -> 371.00687 | E17: =DCF!C21/(1+$B17)^0.5+DCF!F21/(1+$B17)^1.5+DCF!I21/(1+$B17)^2.5+DCF!L21/(1+$B17)^3.5+DCF!O21/(1+$B17)^4.5+(DCF!O12*15)/(1+$B17)^5 -> 431.11517 | F17: =DCF!C21/(1+$B17)^0.5+DCF!F21/(1+$B17)^1.5+DCF!I21/(1+$B17)^2.5+DCF!L21/(1+$B17)^3.5+DCF!O21/(1+$B17)^4.5+(DCF!O12*17.5)/(1+$B17)^5 -> 491.22347 | G17: =DCF!C21/(1+$B17)^0.5+DCF!F21/(1+$B17)^1.5+DCF!I21/(1+$B17)^2.5+DCF!L21/(1+$B17)^3.5+DCF!O21/(1+$B17)^4.5+(DCF!O12*20)/(1+$B17)^5 -> 551.33177
B18: 0.095 | C18: =DCF!C21/(1+$B18)^0.5+DCF!F21/(1+$B18)^1.5+DCF!I21/(1+$B18)^2.5+DCF!L21/(1+$B18)^3.5+DCF!O21/(1+$B18)^4.5+(DCF!O12*10)/(1+$B18)^5 -> 298.37442 | D18: =DCF!C21/(1+$B18)^0.5+DCF!F21/(1+$B18)^1.5+DCF!I21/(1+$B18)^2.5+DCF!L21/(1+$B18)^3.5+DCF!O21/(1+$B18)^4.5+(DCF!O12*12.5)/(1+$B18)^5 -> 355.78772 | E18: =DCF!C21/(1+$B18)^0.5+DCF!F21/(1+$B18)^1.5+DCF!I21/(1+$B18)^2.5+DCF!L21/(1+$B18)^3.5+DCF!O21/(1+$B18)^4.5+(DCF!O12*15)/(1+$B18)^5 -> 413.20103 | F18: =DCF!C21/(1+$B18)^0.5+DCF!F21/(1+$B18)^1.5+DCF!I21/(1+$B18)^2.5+DCF!L21/(1+$B18)^3.5+DCF!O21/(1+$B18)^4.5+(DCF!O12*17.5)/(1+$B18)^5 -> 470.61433 | G18: =DCF!C21/(1+$B18)^0.5+DCF!F21/(1+$B18)^1.5+DCF!I21/(1+$B18)^2.5+DCF!L21/(1+$B18)^3.5+DCF!O21/(1+$B18)^4.5+(DCF!O12*20)/(1+$B18)^5 -> 528.02763
B19: 0.105 | C19: =DCF!C21/(1+$B19)^0.5+DCF!F21/(1+$B19)^1.5+DCF!I21/(1+$B19)^2.5+DCF!L21/(1+$B19)^3.5+DCF!O21/(1+$B19)^4.5+(DCF!O12*10)/(1+$B19)^5 -> 286.49429 | D19: =DCF!C21/(1+$B19)^0.5+DCF!F21/(1+$B19)^1.5+DCF!I21/(1+$B19)^2.5+DCF!L21/(1+$B19)^3.5+DCF!O21/(1+$B19)^4.5+(DCF!O12*12.5)/(1+$B19)^5 -> 341.3563 | E19: =DCF!C21/(1+$B19)^0.5+DCF!F21/(1+$B19)^1.5+DCF!I21/(1+$B19)^2.5+DCF!L21/(1+$B19)^3.5+DCF!O21/(1+$B19)^4.5+(DCF!O12*15)/(1+$B19)^5 -> 396.21831 | F19: =DCF!C21/(1+$B19)^0.5+DCF!F21/(1+$B19)^1.5+DCF!I21/(1+$B19)^2.5+DCF!L21/(1+$B19)^3.5+DCF!O21/(1+$B19)^4.5+(DCF!O12*17.5)/(1+$B19)^5 -> 451.08033 | G19: =DCF!C21/(1+$B19)^0.5+DCF!F21/(1+$B19)^1.5+DCF!I21/(1+$B19)^2.5+DCF!L21/(1+$B19)^3.5+DCF!O21/(1+$B19)^4.5+(DCF!O12*20)/(1+$B19)^5 -> 505.94234
B20: 0.115 | C20: =DCF!C21/(1+$B20)^0.5+DCF!F21/(1+$B20)^1.5+DCF!I21/(1+$B20)^2.5+DCF!L21/(1+$B20)^3.5+DCF!O21/(1+$B20)^4.5+(DCF!O12*10)/(1+$B20)^5 -> 275.21923 | D20: =DCF!C21/(1+$B20)^0.5+DCF!F21/(1+$B20)^1.5+DCF!I21/(1+$B20)^2.5+DCF!L21/(1+$B20)^3.5+DCF!O21/(1+$B20)^4.5+(DCF!O12*12.5)/(1+$B20)^5 -> 327.6648 | E20: =DCF!C21/(1+$B20)^0.5+DCF!F21/(1+$B20)^1.5+DCF!I21/(1+$B20)^2.5+DCF!L21/(1+$B20)^3.5+DCF!O21/(1+$B20)^4.5+(DCF!O12*15)/(1+$B20)^5 -> 380.11037 | F20: =DCF!C21/(1+$B20)^0.5+DCF!F21/(1+$B20)^1.5+DCF!I21/(1+$B20)^2.5+DCF!L21/(1+$B20)^3.5+DCF!O21/(1+$B20)^4.5+(DCF!O12*17.5)/(1+$B20)^5 -> 432.55594 | G20: =DCF!C21/(1+$B20)^0.5+DCF!F21/(1+$B20)^1.5+DCF!I21/(1+$B20)^2.5+DCF!L21/(1+$B20)^3.5+DCF!O21/(1+$B20)^4.5+(DCF!O12*20)/(1+$B20)^5 -> 485.00151
A22: Highlighted cell = Base case (WACC 9.5%, exit 15× EBITDA)
A23: Note: EBITDA 2030 Base = DCF!O12. FCF 2030 Base = DCF!O21. TV sensitivity driven primarily by terminal year.

Sheet Margin_path
A1: MARGIN PATH SENSITIVITY — EV impact of timing (Base case rev. & WACC fixed)
A2: All paths: identical Base revenue growth, WACC 9.5%, TG 2.5%, Capex 2.7%, ΔBFR 7%, tax 22%. Only EBITDA trajectory differs.
B4: Linear (point est.) | C4: Front-loaded | D4: Back-loaded | E4: Notes
A5: EBITDA margin FY25 (anchor) | B5: =Inputs!C21 -> 0.21792367 | C5: =Inputs!C21 -> 0.21792367 | D5: =Inputs!C21 -> 0.21792367
A6: EBITDA margin 2030 target | B6: =Inputs!C22 -> 0.32 | C6: =Inputs!C22 -> 0.32 | D6: =Inputs!C22 -> 0.32
A8: ANNUAL EBITDA MARGIN BY PATH
A9: 2026 | B9: =C5+(C6-C5)*0.2 -> 0.23833893 | C9: =C5+(C6-C5)*0.3 -> 0.24854657 | D9: =C5+(C6-C5)*0.1 -> 0.2281313 | E9: lin=0.20 · front=0.30 · back=0.10
A10: 2027 | B10: =C5+(C6-C5)*0.4 -> 0.2587542 | C10: =C5+(C6-C5)*0.52 -> 0.27100336 | D10: =C5+(C6-C5)*0.26 -> 0.24446351 | E10: lin=0.40 · front=0.52 · back=0.26
A11: 2028 | B11: =C5+(C6-C5)*0.6 -> 0.27916947 | C11: =C5+(C6-C5)*0.72 -> 0.29141863 | D11: =C5+(C6-C5)*0.48 -> 0.26692031 | E11: lin=0.60 · front=0.72 · back=0.48
A12: 2029 | B12: =C5+(C6-C5)*0.8 -> 0.29958473 | C12: =C5+(C6-C5)*0.88 -> 0.30775084 | D12: =C5+(C6-C5)*0.73 -> 0.29243939 | E12: lin=0.80 · front=0.88 · back=0.73
A13: 2030 | B13: =C5+(C6-C5)*1 -> 0.32 | C13: =C5+(C6-C5)*1 -> 0.32 | D13: =C5+(C6-C5)*1 -> 0.32 | E13: lin=1.00 · front=1.00 · back=1.00
A15: EBITDA & FCF BY PATH (€m) — Revenue = DCF Base scenario
A16: EBITDA 2026 | B16: =DCF!C7*(C5+(C6-C5)*0.2) -> 17.126254 | C16: =DCF!C7*(C5+(C6-C5)*0.3) -> 17.859741 | D16: =DCF!C7*(C5+(C6-C5)*0.1) -> 16.392767 | E16: Rev ref: DCF!C7
A17: EBITDA 2027 | B17: =DCF!F7*(C5+(C6-C5)*0.4) -> 21.382212 | C17: =DCF!F7*(C5+(C6-C5)*0.52) -> 22.394424 | D17: =DCF!F7*(C5+(C6-C5)*0.26) -> 20.201298 | E17: Rev ref: DCF!F7
A18: EBITDA 2028 | B18: =DCF!I7*(C5+(C6-C5)*0.6) -> 26.068233 | C18: =DCF!I7*(C5+(C6-C5)*0.72) -> 27.212033 | D18: =DCF!I7*(C5+(C6-C5)*0.48) -> 24.924433 | E18: Rev ref: DCF!I7
A19: EBITDA 2029 | B19: =DCF!L7*(C5+(C6-C5)*0.8) -> 31.051768 | C19: =DCF!L7*(C5+(C6-C5)*0.88) -> 31.89818 | D19: =DCF!L7*(C5+(C6-C5)*0.73) -> 30.311158 | E19: Rev ref: DCF!L7
A20: EBITDA 2030 | B20: =DCF!O7*(C5+(C6-C5)*1) -> 36.152899 | C20: =DCF!O7*(C5+(C6-C5)*1) -> 36.152899 | D20: =DCF!O7*(C5+(C6-C5)*1) -> 36.152899 | E20: Rev ref: DCF!O7
A21: FCF 2026 | B21: =(B16-DCF!C7*Inputs!C30)*(1-Inputs!C31)+DCF!C7*Inputs!C30-DCF!C7*Inputs!C32-(DCF!C7-Inputs!C6)*Inputs!C33 -> 11.003666 | C21: =(C16-DCF!C7*Inputs!C30)*(1-Inputs!C31)+DCF!C7*Inputs!C30-DCF!C7*Inputs!C32-(DCF!C7-Inputs!C6)*Inputs!C33 -> 11.575786 | D21: =(D16-DCF!C7*Inputs!C30)*(1-Inputs!C31)+DCF!C7*Inputs!C30-DCF!C7*Inputs!C32-(DCF!C7-Inputs!C6)*Inputs!C33 -> 10.431546
A22: FCF 2027 | B22: =(B17-DCF!F7*Inputs!C30)*(1-Inputs!C31)+DCF!F7*Inputs!C30-DCF!F7*Inputs!C32-(DCF!F7-DCF!C7)*Inputs!C33 -> 14.056074 | C22: =(C17-DCF!F7*Inputs!C30)*(1-Inputs!C31)+DCF!F7*Inputs!C30-DCF!F7*Inputs!C32-(DCF!F7-DCF!C7)*Inputs!C33 -> 14.845599 | D22: =(D17-DCF!F7*Inputs!C30)*(1-Inputs!C31)+DCF!F7*Inputs!C30-DCF!F7*Inputs!C32-(DCF!F7-DCF!C7)*Inputs!C33 -> 13.134961
A23: FCF 2028 | B23: =(B18-DCF!I7*Inputs!C30)*(1-Inputs!C31)+DCF!I7*Inputs!C30-DCF!I7*Inputs!C32-(DCF!I7-DCF!F7)*Inputs!C33 -> 17.470903 | C23: =(C18-DCF!I7*Inputs!C30)*(1-Inputs!C31)+DCF!I7*Inputs!C30-DCF!I7*Inputs!C32-(DCF!I7-DCF!F7)*Inputs!C33 -> 18.363066 | D23: =(D18-DCF!I7*Inputs!C30)*(1-Inputs!C31)+DCF!I7*Inputs!C30-DCF!I7*Inputs!C32-(DCF!I7-DCF!F7)*Inputs!C33 -> 16.578739
A24: FCF 2029 | B24: =(B19-DCF!L7*Inputs!C30)*(1-Inputs!C31)+DCF!L7*Inputs!C30-DCF!L7*Inputs!C32-(DCF!L7-DCF!I7)*Inputs!C33 -> 21.158894 | C24: =(C19-DCF!L7*Inputs!C30)*(1-Inputs!C31)+DCF!L7*Inputs!C30-DCF!L7*Inputs!C32-(DCF!L7-DCF!I7)*Inputs!C33 -> 21.819095 | D24: =(D19-DCF!L7*Inputs!C30)*(1-Inputs!C31)+DCF!L7*Inputs!C30-DCF!L7*Inputs!C32-(DCF!L7-DCF!I7)*Inputs!C33 -> 20.581218
A25: FCF 2030 | B25: =(B20-DCF!O7*Inputs!C30)*(1-Inputs!C31)+DCF!O7*Inputs!C30-DCF!O7*Inputs!C32-(DCF!O7-DCF!L7)*Inputs!C33 -> 24.992972 | C25: =(C20-DCF!O7*Inputs!C30)*(1-Inputs!C31)+DCF!O7*Inputs!C30-DCF!O7*Inputs!C32-(DCF!O7-DCF!L7)*Inputs!C33 -> 24.992972 | D25: =(D20-DCF!O7*Inputs!C30)*(1-Inputs!C31)+DCF!O7*Inputs!C30-DCF!O7*Inputs!C32-(DCF!O7-DCF!L7)*Inputs!C33 -> 24.992972
A27: PV(FCF) & TERMINAL VALUE BY PATH (€m)
A28: PV(FCF 2026) | B28: =B21/(1+Inputs!C37)^0.5 -> 10.51551 | C28: =C21/(1+Inputs!C37)^0.5 -> 11.062249 | D28: =D21/(1+Inputs!C37)^0.5 -> 9.968771
A29: PV(FCF 2027) | B29: =B22/(1+Inputs!C37)^1.5 -> 12.267127 | C29: =C22/(1+Inputs!C37)^1.5 -> 12.956168 | D29: =D22/(1+Inputs!C37)^1.5 -> 11.463246
A30: PV(FCF 2028) | B30: =B23/(1+Inputs!C37)^2.5 -> 13.924514 | C30: =C23/(1+Inputs!C37)^2.5 -> 14.635579 | D30: =D23/(1+Inputs!C37)^2.5 -> 13.213449
A31: PV(FCF 2029) | B31: =B24/(1+Inputs!C37)^3.5 -> 15.400809 | C31: =C24/(1+Inputs!C37)^3.5 -> 15.881347 | D31: =D24/(1+Inputs!C37)^3.5 -> 14.98034
A32: PV(FCF 2030) | B32: =B25/(1+Inputs!C37)^4.5 -> 16.613241 | C32: =C25/(1+Inputs!C37)^4.5 -> 16.613241 | D32: =D25/(1+Inputs!C37)^4.5 -> 16.613241
A33: Sum PV(FCF) (€m) | B33: =SUM(B28:B32) -> 68.721201 | C33: =SUM(C28:C32) -> 71.148583 | D33: =SUM(D28:D32) -> 66.239046
A34: Terminal Value (Gordon Growth) (€m) | B34: =B25*(1+Inputs!C38)/(Inputs!C37-Inputs!C38)/(1+Inputs!C37)^5 -> 232.47333 | C34: =C25*(1+Inputs!C38)/(Inputs!C37-Inputs!C38)/(1+Inputs!C37)^5 -> 232.47333 | D34: =D25*(1+Inputs!C38)/(Inputs!C37-Inputs!C38)/(1+Inputs!C37)^5 -> 232.47333
A35: Enterprise Value (€m) | B35: =B33+B34 -> 301.19453 | C35: =C33+C34 -> 303.62191 | D35: =D33+D34 -> 298.71237
A36: EV spread vs. linear (€m) | B36: =B35-B35 -> 0 | C36: =C35-B35 -> 2.4273818 | D36: =D35-B35 -> -2.4821548
A37: EV spread vs. linear (%) | B37: =0 -> 0 | C37: =IF(B35=0,0,(C35-B35)/B35) -> 0.0080591828 | D37: =IF(B35=0,0,(D35-B35)/B35) -> -0.0082410354
A39: Point estimate for all other tabs: Linear interpolation (col B). Front-loaded / back-loaded show ±EV sensitivity.

Sheet Trading_comps
A1: TRADING COMPS — SaaS B2B / Finance Automation / O2C peers | VALORISATION AU 15/07/2026
A2: Cours du 15/07/2026 (cotations intraday désynchronisées — précision au jour) ; EUR/USD 1,1424 au 15/07/2026 ; guidances publiées en mai 2026. Méthode PRIMAIRE : EV/Sales forward (guidance midpoint). Méthode de CONTRÔLE : EV/résultat opérationnel non-GAAP — ce n'est PAS un EBITDA (D&A non réintégrée, SBC exclue selon les émetteurs) : proxy assumé, homogénéité imparfaite entre peers.
A4: Company | B4: Ticker | C4: Cours USD | D4: EV (€m) | E4: Rev fwd guidée (€m) | F4: Rés. op. non-GAAP (€m) | G4: EV/Sales fwd | H4: EV/OpInc | I4: Période guidée / note
A5: BlackLine | B5: BL US | C5: 28.75 | D5: 1635 | E5: 671.4 | F5: 162.8 | G5: =D5/E5 -> 2.43521 | H5: =D5/F5 -> 10.042998 | I5: FY26 clos 31/12/26 — calendaire 2026 ; marge op. 24,0-24,5%
A6: BILL Holdings | B6: BILL US | C6: 42.72 | D6: 3428 | E6: 1441.7 | F6: 267.9 | G6: =D6/E6 -> 2.3777485 | H6: =D6/F6 -> 12.795819 | I6: FY26 clos 30/06/26 — QUASI-TRAILING (exercice déjà clos) ; fonds clients neutralisés dans l'EV ; core revenue 1 501 M$ (EV/core 2,61x)
A7: nCino | B7: NCNO US | C7: 17.48 | D7: 1829 | E7: 563.7 | F7: 147.5 | G7: =D7/E7 -> 3.2446337 | H7: =D7/F7 -> 12.4 | I7: FY27 clos 31/01/27 ≈ calendaire 2026 ; FCF guidé 135-140 M$
A8: Workiva | B8: WK US | C8: 53.02 | D8: 2538 | E8: 909.5 | F8: 147.8 | G8: =D8/E8 -> 2.7905443 | H8: =D8/F8 -> 17.171854 | I8: FY26 clos 31/12/26 — calendaire 2026 ; marge op. 16,0-16,5% ; FCF ≈ 20%
A9: Esker (réf.)* | B9: (retirée de la cote) | D9: 1576 | E9: 205.3 | G9: =D9/E9 -> 7.6765709 | I9: * Deal Bridgepoint/GA 2024 : ~7,7x CA 2024A / ~6,9x NTM (doc offre). Référence M&A, exclue des agrégats.
A11: AGRÉGATS (4 peers cotés, hors Esker)
A12: Médiane | G12: =MEDIAN(G5:G8) -> 2.6128771 | H12: =MEDIAN(H5:H8) -> 12.59791
A13: Min | G13: =MIN(G5:G8) -> 2.3777485 | H13: =MIN(H5:H8) -> 10.042998
A14: Max | G14: =MAX(G5:G8) -> 3.2446337 | H14: =MAX(H5:H8) -> 17.171854
A16: IMPLIED EV SIDETRADE — multiples appliqués aux estimations 2026E Base
A17: Sidetrade Revenue 2026E (Base, €m) | E17: =DCF!C7 -> 71.85672
A18: Sidetrade EBITDA 2026E (Base, €m — incl. CIR) | F18: =DCF!C12 -> 17.126254
A20: Fourchette | E20: Low (min peers) | F20: Mid (médiane) | G20: High (max peers)
A21: Multiple EV/Sales fwd — dérivé de la table | E21: =G13 -> 2.3777485 | F21: =G12 -> 2.6128771 | G21: =G14 -> 3.2446337
A22: EV implicite via EV/Sales (€m) | E22: =E21*$E$17 -> 170.85721 | F22: =F21*$E$17 -> 187.75278 | G22: =G21*$E$17 -> 233.14873
A23: Multiple EV/OpInc (proxy EBITDA) — dérivé de la table | E23: =H13 -> 10.042998 | F23: =H12 -> 12.59791 | G23: =H14 -> 17.171854
A24: EV implicite via proxy EBITDA (€m) | E24: =E23*$F$18 -> 171.99893 | F24: =F23*$F$18 -> 215.755 | G24: =G23*$F$18 -> 294.08953
A26: Fourchette trading retenue (€m EV) | E26: =ROUND(AVERAGE(E22,E24),0) -> 171 | F26: =ROUND(AVERAGE(F22,F24),0) -> 202 | G26: =ROUND(AVERAGE(G22,G24),0) -> 264 | I26: Moyenne des deux méthodes, 100% dérivée de la table : changer un peer change la fourchette et le football field.
A28: Lecture au 15/07/2026 : les peers US se sont fortement dératés vs H1-2025 (médiane EV/Sales fwd ~2,6x vs ~4,7x). La fourchette trading devient un PLANCHER de sentiment de marché US — à confronter à l'EV de marché de Sidetrade elle-même (~282 M€ au 15/07, ~3,9x son CA 2026E) : le marché paie déjà Sidetrade au-dessus du haut de fourchette peers. Écart DCF (301) vs comps = débat de prime assumé (croissance organique + profitabilité + small-cap FR vs mid-caps US), pas une convergence.

Sheet Transaction_comps
A1: TRANSACTION COMPS — Precedent M&A in Office-of-CFO / O2C / Fintech SaaS (control transactions)
A2: All deals include control premium (30-50% vs. trading). Faits verifies et corriges le 15-Jul-2026 (audit 4.5): Billtrust->EQT, Bottomline->Thoma Bravo, Esker EV/CA restates.
A4: Target | B4: Year | C4: Acquirer | D4: Segment | E4: EV (€m) | F4: LTM Rev (€m) | G4: LTM EBITDA (€m) | H4: EV/Sales | I4: EV/EBITDA | J4: Notes
A5: Esker | B5: 2024 | C5: Bridgepoint / GA | D5: O2C / AR automation (France) | E5: 1576 | F5: 205.3 | H5: =E5/F5 -> 7.6765709 | I5: "n.m." | J5: Offre 262 EUR/action (sept. 2024): equity ~1 619 M, EV ~1 576 M; ~7,7x CA 2024A (205,3 M). Doc offre: moyenne transactions ~6,8x NTM Sales. EBITDA LTM non retraite -> exclu des agregats.
A6: Coupa | B6: 2023 | C6: Thoma Bravo | D6: Source-to-pay / procurement | E6: 7273 | F6: 726 | G6: 45 | H6: =E6/F6 -> 10.017906 | I6: =E6/G6 -> 161.62222 | J6: ~$8B; ~11× Sales; EBITDA near breakeven at time of deal
A7: Billtrust | B7: 2022 | C7: EQT Private Equity | D7: AR invoicing / cash app SaaS | E7: 1591 | F7: 195 | G7: 20 | H7: =E7/F7 -> 8.1589744 | I7: =E7/G7 -> 79.55 | J7: ~USD 1,7 Md take-private (annonce sept. 2022); ~9x Sales; scale player AR automation
A8: Pagero | B8: 2024 | C8: Thomson Reuters | D8: E-invoicing / tax compliance | E8: 600 | F8: 90 | G8: 18 | H8: =E8/F8 -> 6.6666667 | I8: =E8/G8 -> 33.333333 | J8: SEK 7.3B (~€0.6B); ~6.7× Sales; ~33× EBITDA
A9: Bottomline Tech. | B9: 2022 | C9: Thoma Bravo | D9: B2B payments / cash management | E9: 2364 | F9: 480 | G9: 100 | H9: =E9/F9 -> 4.925 | I9: =E9/G9 -> 23.64 | J9: ~$2.6B; ~5.4× Sales; ~26× EBITDA. Mature but OCF-positive
A11: AGGREGATES
A12: Median | H12: =MEDIAN(H5:H9) -> 7.6765709 | I12: =MEDIAN(I7,I8,I9) -> 33.333333 | J12: Coupa (161x n/m) et Esker (EBITDA n.d.) exclus des agregats EV/EBITDA
A13: Min | H13: =MIN(H5:H9) -> 4.925 | I13: =MIN(I7,I8,I9) -> 23.64
A14: Max | H14: =MAX(H5:H9) -> 10.017906 | I14: =MAX(I7,I8,I9) -> 79.55
A16: IMPLIED CONTROL EV FOR SIDETRADE
A17: Esker deal most comparable (same vertical, Euronext Growth, O2C). Discount applied for size & liquidity.
A19: Sidetrade Revenue FY25 (€m) | F19: =Inputs!B6 -> 61.416
A20: Sidetrade Revenue 2026E Base (€m) | F20: =DCF!C7 -> 71.85672
A21: Sidetrade EBITDA FY25 (€m) | G21: =Inputs!B7 -> 13.384
A23: Implied EV range — control (€m) | E23: Low | F23: Base control | G23: High
A24: EV/Sales multiple applied | E24: 4.7 | F24: 6.7 | G24: 8.9 | J24: Low = Bottomline/Pagero; Mid = Esker; High = Coupa premium. Size discount applied.
A25: Implied EV on FY25 Revenue (€m) | E25: =F19*E24 -> 288.6552 | F25: =F19*F24 -> 411.4872 | G25: =F19*G24 -> 546.6024
A27: Selected transaction comp range (€m EV) | E27: =ROUND(E25,0) -> 289 | F27: =ROUND(F25,0) -> 411 | G27: =ROUND(G25,0) -> 547 | J27: Derive des multiples ligne 24 (mid = moyenne doc offre Esker ~6,8x NTM avec decote taille). Control premium ~40% vs stand-alone.
A29: IMPORTANT: Transaction comps include control premium. NOT directly comparable to DCF or trading comp EV.

Sheet LBO_old
A1: OBSOLETE — DO NOT USE · LBO AFFORDABILITY MODEL v1 (simplified) — superseded by LBO_full on 15-Jul-2026
A2: OBSOLETE (kept for build history only — figures inconsistent with the current model). Simplified LBO: all unlevered FCF applied to debt service, exit at fixed EBITDA multiple yr 5, entry leverage 35% of EV.
A4: ASSUMPTIONS (cross-linked from Inputs)
A5: Entry leverage (Debt / Entry EV) | B5: =Inputs!B42 -> 0.35 | I5: Inputs!B42
A6: LBO exit multiple (×EBITDA) | B6: =Inputs!B43 -> 15
A7: Hold period (years) | B7: 5
A8: Base WACC (reference) | B8: =Inputs!C37 -> 0.095
A10: BASE CASE PROJECTIONS from DCF tab (€m) | C10: 2026 | D10: 2027 | E10: 2028 | F10: 2029 | G10: 2030 | H10: CUM 5yr
A11: Revenue (€m) | C11: =DCF!C7 -> 71.85672 | D11: =DCF!F7 -> 82.635228 | E11: =DCF!I7 -> 93.377808 | F11: =DCF!L7 -> 103.64937 | G11: =DCF!O7 -> 112.97781 | H11: =SUM(C11:G11) -> 464.49693
A12: EBITDA (€m) | C12: =DCF!C12 -> 17.126254 | D12: =DCF!F12 -> 21.382212 | E12: =DCF!I12 -> 26.068233 | F12: =DCF!L12 -> 31.051768 | G12: =DCF!O12 -> 36.152899 | H12: =SUM(C12:G12) -> 131.78137
A13: Unlevered FCF (€m) | C13: =DCF!C21 -> 11.003666 | D13: =DCF!F21 -> 14.056074 | E13: =DCF!I21 -> 17.470903 | F13: =DCF!L21 -> 21.158894 | G13: =DCF!O21 -> 24.992972 | H13: =SUM(C13:G13) -> 88.682508
A14: Cumulative FCF (running total) | C14: =C13 -> 11.003666 | D14: =C14+D13 -> 25.05974 | E14: =D14+E13 -> 42.530642 | F14: =E14+F13 -> 63.689537 | G14: =F14+G13 -> 88.682508
A16: EXIT METRICS (Base Case, Year 5)
A17: EBITDA 2030 — Base (€m) | B17: =DCF!O12 -> 36.152899
A18: Exit EV = EBITDA₂₀₃₀ × exit multiple (€m) | B18: =B17*B6 -> 542.29349
A20: LBO AFFORDABILITY — Max Entry EV per IRR target | B20: IRR target | C20: Max Entry EV (€m) | D20: Entry Equity (€m) | E20: Entry Debt (€m) | F20: EV / EBITDA FY25 (×) | I20: Notes
A21: Conservative | B21: 0.18 | C21: =(B18+H13)/($B$5+(1-$B$5)*(1+B21)^5) -> 343.47381 | D21: =C21*(1-$B$5) -> 223.25797 | E21: =C21*$B$5 -> 120.21583 | F21: =C21/Inputs!B7 -> 25.663016 | I21: Conservative — minimum PE return threshold
A22: Base / Target | B22: 0.225 | C22: =(B18+H13)/($B$5+(1-$B$5)*(1+B22)^5) -> 294.42817 | D22: =C22*(1-$B$5) -> 191.37831 | E22: =C22*$B$5 -> 103.04986 | F22: =C22/Inputs!B7 -> 21.998518 | I22: Base / Target — mid-market PE standard
A23: Aggressive | B23: 0.25 | C23: =(B18+H13)/($B$5+(1-$B$5)*(1+B23)^5) -> 270.38245 | D23: =C23*(1-$B$5) -> 175.74859 | E23: =C23*$B$5 -> 94.633857 | F23: =C23/Inputs!B7 -> 20.201916 | I23: High-conviction / aggressive return target
A24: Formula: Entry EV = (Exit EV + Cumulative FCF) / [ Leverage + (1 − Leverage) × (1 + IRR)⁵ ]
A26: VERIFICATION — at DCF Base EV (implied IRR check)
A27: Entry EV (DCF Base Gordon, €m) | B27: =DCF!R34 -> 301.19453
A28: Entry equity (€m) | B28: =B27*(1-B5) -> 195.77644
A29: Entry debt (€m) | B29: =B27*B5 -> 105.41808
A30: Cumulative FCF 5yr (€m) | B30: =H13 -> 88.682508
A31: Exit equity = max(0, Exit EV + CumFCF – Debt) | B31: =MAX(0,B18+B30-B29) -> 525.55791
A32: Money-on-Money (×) | B32: =IF(B28=0,0,B31/B28) -> 2.6844798
A33: Implied 5-yr IRR | B33: =IF(B32<=0,0,(B32)^(1/5)-1) -> 0.21834989 | I33: Should ≈ 22.5% if DCF Base EV ≈ affordability at IRR 22.5%
A35: LBO range selected (€m EV) | C35: 135 | D35: 283 | E35: 455 | I35: Low=IRR 25%, Base=IRR 22.5%, High=IRR 18% (strategic patience buyer)

Sheet LBO_full
A1: SIDETRADE — LBO MODEL (FULL)
A2: Build v2.1 · 15-Jul-2026 (CIR single-count fix, comps refresh 15/07, WACC bridge, Checks sheet) · originally v1.0 10-Jun-2026 per Build Spec v3 · Blue = input · Black = formula · Green = cross-sheet link
A3: Interest on OPENING debt (documented non-circular variant, Spec §3.4). Engine-solved values flagged in Source column.
A4: 0 — COCKPIT
A5: Deal snapshot
A6: New TLB / leverage / all-in rate | B6: =B27 -> 53.536 | C6: =B26 -> 4 | D6: =B25 -> 0.07163
A7: Sweep / exit multiple / rollover | B7: =B29 -> 0.75 | C7: =B36 -> 15 | D7: =B35 -> 0.35
A9: Live results (at Entry EV inputs, row 50) | B9: Bear | C9: Base | D9: Bull
A10: Entry EV (€m) | B10: =B50 -> 169.7 | C10: =C50 -> 241.9 | D10: =D50 -> 297.3
A11: Sponsor IRR (5y) | B11: =C112 -> 0.22509033 | C11: =C150 -> 0.2250377 | D11: =C188 -> 0.22495363
A12: Sponsor MoM | B12: =C113 -> 2.7595645 | C12: =C151 -> 2.7589718 | D12: =C189 -> 2.7580253
A13: S&U balance check (must be 0) | B13: =B68 -> 0 | C13: =C68 -> 0 | D13: =D68 -> 0
A15: Affordability — max Entry EV (€m) per target IRR [engine-solved] | B15: IRR 18% | C15: IRR 22.5% | D15: IRR 25%
A16: Bear | B16: 196.5 | C16: 169.7 | D16: 157.2 | I16: Old hardcoded range was 135 / 283 / 455 — replaced. New range is tighter and honest:
A17: Base | B17: 283.5 | C17: 241.9 | D17: 222.5 | I17: entry ~18x EBITDA vs exit 15x = multiple compression caps sponsor pricing below DCF fair value.
A18: Bull | B18: 350.2 | C18: 297.3 | D18: 272.5
A21: 1 — INPUT BLOCK (Cat A = verified regulatory/primary · B = market standard · C = Sidetrade-specific · D = modelling assumption)
A22: Parameter | B22: Value | C22: Cat | I22: Source
A23: Euribor 3M (09-Jun-2026) | B23: 0.02373 | C23: B | I23: euribor-rates.eu, verified 09-Jun-2026 (2.373%)
A24: TLB spread over Euribor (B-rated median) | B24: 0.0479 | C24: B | I24: S&P Eur LevFin Monthly Mar-2026 (s101674532) — gated, to reconfirm at final pass
A25: All-in TLB rate | B25: =B23+B24 -> 0.07163 | C25: — | I25: Calculated
A26: Entry leverage (x EBITDA FY25) | B26: 4 | C26: B | I26: Capstone Mid-Market LevFin Q1-2026: total 4.0–6.0x, senior 3.0–4.5x — taken at senior mid
A27: New TLB (€m) | B27: =B26*Inputs!B7 -> 53.536 | C27: — | I27: Note: leverage x EBITDA FY25 (Inputs!B7)
A28: Mandatory amortisation (% of original TLB p.a.) | B28: 0.01 | C28: B | I28: European TLB convention (1%/yr, bullet at maturity)
A29: Cash sweep (% of excess FCF) | B29: 0.75 | C29: B | I29: European LevFin convention 50–75% — upper end at 4x leverage
A30: Minimum cash on balance sheet (€m) | B30: 8 | C30: D | I30: Assumption — modelling: ~1 month OpEx (Sidetrade OpEx ~€48m/yr). Sens. 5–12
A31: Transaction fees (% of Entry EV) | B31: 0.03 | C31: B | I31: Firmex M&A Fee Guide 2024-25 EU: 3–5% for €10-30m EBITDA targets — taken at low end
A32: Financing fees (% of new TLB) | B32: 0.03 | C32: B | I32: Arrangement 2.5-2.75% + OID 1-2% ~ 3% blended (Cleary Gottlieb EU LevFin)
A33: RCF commitment fee (€m p.a.) | B33: 0.075 | C33: D | I33: Assumption: 50bps x €15m undrawn RCF
A34: Novasque ownership (pre-deal) | B34: 0.35 | C34: C | I34: Sidetrade PR Feb-2026 (Briarwood release): founder holds 35%
A35: Rollover (% of Novasque consideration) | B35: 0.35 | C35: D | I35: Assumption — founder staying active: 25–40% band (WSP/Auxo). Sens. 25–50%
A36: Exit multiple (x EBITDA 2030) | B36: 15 | C36: D | I36: Note: TV cross-check multiple (Inputs!B39). Conservative vs trading comps 22-25x. Sens. 12-19x
A37: IS rate (normal) | B37: 0.25 | C37: A | I37: CGI art. 219 (LEGIARTI000053542939)
A38: Social contribution on IS | B38: 0.033 | C38: A | I38: CGI art. 235 ter ZC — 3.3% of IS above €0.763m
A39: Social contribution threshold (€m) | B39: 0.763 | C39: A | I39: CGI art. 235 ter ZC
A40: CIR — flat, included in DCF EBITDA; non-taxable, no tax-line offset (€m) | B40: =Inputs!B34 -> 3.5 | C40: A | I40: FY25 actual €3.482m (Note 22); flat per DCF assumption Inputs!B34
A41: Net debt pre-deal — strict (€m) | B41: =FY25_base!B49 -> 14.654 | C41: A | I41: Stat Report p.3/p.18/p.20: 30.981 − 16.327 = 14.654
A42: Gross financial debt pre-deal (€m) | B42: =FY25_base!B46 -> 30.981 | C42: A | I42: Stat Report Note 10 (5 tranches, w.avg ~2.4% — refinanced at close)
A43: Cash + marketable securities pre-deal (€m) | B43: =-(FY25_base!B47+FY25_base!B48) -> 16.327 | C43: A | I43: Stat Report Note 6: 5.402 + 10.925
A44: Earn-outs settled at close (€m) | B44: 0.455 | C44: C | I44: Note 29: Amalto 277k + CreditPoint 178k provisioned
...

Sheet Football_field
A1: FOOTBALL FIELD — Enterprise Value Summary (€m)
A2: Stand-alone vs. control case across four valuation methods | Base case = DCF Gordon Growth
B4: Low (€m) | C4: Base (€m) | D4: High (€m) | E4: EV/EBITDA FY25 (Base) | F4: EV/Sales FY25 (Base) | G4: Interpretation
A5: DCF — stand-alone (Gordon) | B5: =DCF!Q34 -> 157.92189 | C5: =DCF!R34 -> 301.19453 | D5: =DCF!S34 -> 497.11514 | E5: =C5/Inputs!B7 -> 22.504074 | F5: =C5/Inputs!B6 -> 4.9041703 | G5: Intrinsic fundamental value; linear margin path
A6: Trading comps | B6: =Trading_comps!E26 -> 171 | C6: =Trading_comps!F26 -> 202 | D6: =Trading_comps!G26 -> 264 | E6: =C6/Inputs!B7 -> 15.092648 | F6: =C6/Inputs!B6 -> 3.2890452 | G6: Market-based, stand-alone — no control premium
A7: Transaction comps (control) | B7: =Transaction_comps!E27 -> 289 | C7: =Transaction_comps!F27 -> 411 | D7: =Transaction_comps!G27 -> 547 | E7: =C7/Inputs!B7 -> 30.708308 | F7: =C7/Inputs!B6 -> 6.6920672 | G7: Control premium ~40% vs. stand-alone; M&A scenario
A8: LBO affordability | B8: =LBO_full!D199 -> 222.5 | C8: =LBO_full!C199 -> 241.9 | D8: =LBO_full!B199 -> 283.5 | E8: =C8/Inputs!B7 -> 18.073819 | F8: =C8/Inputs!B6 -> 3.938713 | G8: Sponsor affordability (IRR 25% / 22.5% / 18%) — full LBO model, see LBO_full tab
A10: KEY CONCLUSIONS
A11: Central stand-alone EV (€m) | C11: =DCF!R34 -> 301.19453
A12: Control / M&A case EV (€m) | C12: =Transaction_comps!F27 -> 411
A13: Core stand-alone range (DCF + Trading comps) (€m) | B13: =DCF!Q34 -> 157.92189 | C13: to | D13: =Trading_comps!G26 -> 264
A14: MARKET CHECK — EV de marché Sidetrade (ALBFR) au 15/07/2026 | B14: =170*FY25_base!B69/1000000+FY25_base!B49 -> 275.9083 | C14: =174*FY25_base!B69/1000000+FY25_base!B49 -> 282.05546 | D14: =175.2*FY25_base!B69/1000000+FY25_base!B49 -> 283.89961 | E14: =C14/Inputs!B7 -> 21.074078 | F14: =C14/Inputs!B6 -> 4.5925404 | G14: Cours 174,00 € (+0,35%, fourchette du jour 170,00-175,20) x 1 536 790 actions diluées + dette nette stricte 14,7. Le DCF Base (301) ressort ~7% au-dessus du marché ; le marché paie Sidetrade au-dessus du haut de fourchette des peers US dératés.
A15: VISUAL RANGE MAP (0 – 600 €m scale)
A16: DCF | B16: =REPT("░",ROUND(B5/600*48,0))&REPT("█",MAX(1,ROUND((D5-B5)/600*48,0)))&REPT("░",MAX(0,48-ROUND(B5/600*48,0)-MAX(1,ROUND((D5-B5)/600*48,0)))) -> ░░░░░░░░░░░░░███████████████████████████░░░░░░░░ | C16: ="Low €"&TEXT(B5,"0")&"m | Base €"&TEXT(C5,"0")&"m | High €"&TEXT(D5,"0")&"m" -> Low €158m | Base €301m | High €497m
A17: Trading | B17: =REPT("░",ROUND(B6/600*48,0))&REPT("█",MAX(1,ROUND((D6-B6)/600*48,0)))&REPT("░",MAX(0,48-ROUND(B6/600*48,0)-MAX(1,ROUND((D6-B6)/600*48,0)))) -> ░░░░░░░░░░░░░░███████░░░░░░░░░░░░░░░░░░░░░░░░░░░ | C17: ="Low €"&TEXT(B6,"0")&"m | Base €"&TEXT(C6,"0")&"m | High €"&TEXT(D6,"0")&"m" -> Low €171m | Base €202m | High €264m
A18: Tx Comps | B18: =REPT("░",ROUND(B7/600*48,0))&REPT("█",MAX(1,ROUND((D7-B7)/600*48,0)))&REPT("░",MAX(0,48-ROUND(B7/600*48,0)-MAX(1,ROUND((D7-B7)/600*48,0)))) -> ░░░░░░░░░░░░░░░░░░░░░░░█████████████████████░░░░ | C18: ="Low €"&TEXT(B7,"0")&"m | Base €"&TEXT(C7,"0")&"m | High €"&TEXT(D7,"0")&"m" -> Low €289m | Base €411m | High €547m
A19: LBO | B19: =REPT("░",ROUND(B8/600*48,0))&REPT("█",MAX(1,ROUND((D8-B8)/600*48,0)))&REPT("░",MAX(0,48-ROUND(B8/600*48,0)-MAX(1,ROUND((D8-B8)/600*48,0)))) -> ░░░░░░░░░░░░░░░░░░█████░░░░░░░░░░░░░░░░░░░░░░░░░ | C19: ="Low €"&TEXT(B8,"0")&"m | Base €"&TEXT(C8,"0")&"m | High €"&TEXT(D8,"0")&"m" -> Low €223m | Base €242m | High €284m
B20: 0 100 200 300 400 500 600 (€m)

Sheet Equity_bridge
A1: EV → EQUITY → IMPLIED SHARE PRICE (€m unless noted)
A2: Net debt = FY25 actuals (strict). No pro-forma adjustments.
B4: Bear | C4: Base | D4: Bull | E4: Notes
A5: ENTERPRISE VALUE — DCF Gordon Growth (€m)
A6: Enterprise Value (€m) | B6: =DCF!Q34 -> 157.92189 | C6: =DCF!R34 -> 301.19453 | D6: =DCF!S34 -> 497.11514
A8: NET DEBT BRIDGE (€m) — FY25 actuals, no adjustments
A9: Gross financial debt | B9: =FY25_base!B46 -> 30.981 | C9: =FY25_base!B46 -> 30.981 | D9: =FY25_base!B46 -> 30.981 | E9: = €30.981m | FY25_base!B46
A10: – Cash | B10: =FY25_base!B47 -> -5.402 | C10: =FY25_base!B47 -> -5.402 | D10: =FY25_base!B47 -> -5.402 | E10: = –€5.402m | FY25_base!B47
A11: – Marketable securities | B11: =FY25_base!B48 -> -10.925 | C11: =FY25_base!B48 -> -10.925 | D11: =FY25_base!B48 -> -10.925 | E11: = –€10.925m | FY25_base!B48
A12: Net Debt (strict) (€m) | B12: =FY25_base!B49 -> 14.654 | C12: =FY25_base!B49 -> 14.654 | D12: =FY25_base!B49 -> 14.654 | E12: = €14.654m strict. No earn-outs (€0.5m) or deferred rev. adjustments.
A14: EQUITY VALUE (€m)
A15: Equity Value = EV – Net Debt (€m) | B15: =B6-B12 -> 143.26789 | C15: =C6-C12 -> 286.54053 | D15: =D6-D12 -> 482.46114
A17: SHARE PRICE
A18: Diluted shares (thousands) | B18: =FY25_base!B69 -> 1536790 | C18: =FY25_base!B69 -> 1536790 | D18: =FY25_base!B69 -> 1536790 | E18: = 1,536,790 | FY25_base!B69 — Note 30
A19: Diluted shares (millions) | B19: =B18/1000000 -> 1.53679 | C19: =C18/1000000 -> 1.53679 | D19: =D18/1000000 -> 1.53679
A20: Implied share price (€ / share) | B20: =B15/B19 -> 93.225416 | C20: =C15/C19 -> 186.45392 | D20: =D15/D19 -> 313.94083
A22: CONTROL CASE — Transaction Comps (M&A scenario)
A23: EV — control case (€m) | C23: =Transaction_comps!F27 -> 411
A24: Equity Value — control (€m) | C24: =C23-C12 -> 396.346
A25: Implied share price — control (€ / share) | C25: =C24/C19 -> 257.90511 | E25: Control premium case; not a stand-alone fair value.
A27: SUMMARY — BASE CASE (central stand-alone valuation)
A28: Enterprise Value DCF Base (€m) | C28: =C6 -> 301.19453
A29: Net Debt (€m) | C29: =C12 -> 14.654
A30: Equity Value (€m) | C30: =C15 -> 286.54053
A31: Diluted shares (m) | C31: =C19 -> 1.53679
A32: Implied share price (€/share) | C32: =C20 -> 186.45392

Sheet Caveats
A1: CAVEATS & METHODOLOGICAL SENSITIVITIES
A3: Caveat | B3: Details & Rationale | C3: EV impact (approx.) | D3: Recommendation
A4: CIR continuation risk | B4: Model includes €3.5m CIR flat 2026-2030 in EBITDA (= ~27% of R&D spend). Risk: (1) French CIR rules tightened; (2) Sidetrade already exceeded SME threshold → 3yr deferral active; (3) R&D migrates offshore. FY25 CIR €3.482m (up from €2.560m FY24) confirms growing R&D. Management commits to maintaining AI R&D investment. | C4: –€20m to –€40m EV if CIR reduced to zero | D4: Run a CIR-zero stress test. Flag explicitly. Upside: CIR likely grows with R&D (GPU capex + agentic dev).
A5: EBITDA margin path | B5: Base case: linear 22%→32% over 5 years. O2C2030 plan targets 30-35% via: (1) AI-native gross margin 91-94%; (2) internal agentic efficiency programme (+10-15% productivity yr1); (3) subscription leverage. Front-loaded = earlier efficiency gains. Back-loaded = integration drag. Spread: ±3-5% EV quantified in Margin_path tab. | C5: ±3-5% vs. linear base | D5: Linear is conservative and defensible for external use. Front-loaded internally more likely.
A6: Revenue growth assumptions | B6: Base 2026 at +17% matches Q1-2026 reported. Deceleration to 9% by 2030 reflects organic maturation offset by AI-native. Key risks: (a) macro slowing enterprise software spend; (b) ezyCollect SME segment more cyclical; (c) AI-native ramp slower than O2C2030 guidance. Resilience factors: 46.4m avg contract, 85% large enterprise, 92% subscription gross margin. | C6: Bear –50% EV; Bull +70% EV vs. Base | D6: Monitor Q2/Q3-2026. If +17% sustains, upgrade Base to Bull. Bear is genuine stress.
