Workbook

Sheet Lisez-moi
B2: PROJET HERMÈS — MODÈLE DE CARVE-OUT
B3: Opella (Sanofi / CD&R) — coût de l'autonomie et besoin de cash de séparation
B5: Objet | C5: Mesurer ce que coûte l'autonomie d'Opella et ce que la séparation exige en cash, période par période, du closing au régime établi.
B6: Chaîne de vérité | C6: build_carveout.py porte la logique et génère ce workbook, qui est l'artefact contrôlé. Le snapshot JSON est un export sémantique réconcilié au workbook ; il n'est jamais une entrée du générateur.
B7: Calendrier | C7: Le closing du 30/04/2025 est la borne d'origine. 2025 est un stub de 8 mois (P1), pas une année pleine. La TSA se compte en mois contractuels depuis le closing (mois 1 = mai 2025) puis se convertit en périodes calendaires.
B8: Deux registres | C8: Registre comptable pour M2 à M6 : une charge est négative. Registre de besoin pour M7 seul : le besoin est publié en montant positif. Une ligne du cas contribue au besoin pour −montant, une ligne du contrefactuel pour +montant.
B9: Régime établi | C9: Ce n'est pas une hypothèse mais un output daté : première période sans TSA, sans one-off, et avec les coûts stand-alone à 100 % de leur run-rate.
B10: Code couleur | C10: Bleu : entrées modifiables. Noir : formules. Vert : liens inter-onglets. Fond jaune : hypothèse structurante à challenger.
B11: Avertissement | C11: Document de démonstration méthodologique préparé par Hamza Ben Chaouch (ESSEC). Ne constitue ni un conseil, ni une valorisation, ni un underwriting. Les ajustements de carve-out sont des estimations du rédacteur.
B13: REGISTRE DES SOURCES
B14: Id | C14: Source, date de valeur et date de consultation
B15: S1 | C15: Sanofi — annonce de la transaction Opella — organisme : Sanofi — document : Sanofi and CD&R partner to fuel Opella’s ambitions in consumer healthcare — publication : 2024-10-21 — date de valeur 2024-10-21, consultée le 2026-07-29 — périmètre : Annonce de transaction ; EBITDA estimé 2024 — localisation : Communiqué, paragraphe « The valuation of Opella… » — statut : public / primary — fait utilisé : Valeur d’entreprise d’environ 16 Md€ et multiple annoncé d’environ 14x l’EBITDA estimé 2024 — référence exacte : Sanofi — Sanofi and CD&R partner to fuel Opella’s ambitions in consumer healthcare — publié le 2024-10-21 — Communiqué, paragraphe « The valuation of Opella… » — https://www.sanofi.com/en/media-room/press-releases/2024/2024-10-21-05-30-00-2965875 — consultée le 2026-07-29
B16: S2 | C16: Sanofi — closing de la transaction Opella — organisme : Sanofi — document : Sanofi and CD&R close Opella transaction, create global consumer healthcare leader — publication : 2025-04-30 — date de valeur 2025-04-30, consultée le 2026-07-29 — périmètre : Closing et actionnariat au 30 avril 2025 — localisation : Communiqué, premiers paragraphes — statut : public / primary — fait utilisé : closing, participations CD&R 50,0 % / Sanofi 48,2 % / Bpifrance 1,8 %, origine du calendrier — référence exacte : Sanofi — Sanofi and CD&R close Opella transaction, create global consumer healthcare leader — publié le 2025-04-30 — Communiqué, premiers paragraphes — https://www.sanofi.com/en/media-room/press-releases/2025/2025-04-30-11-00-00-3071167 — consultée le 2026-07-29
B17: S3 | C17: Opella et Sanofi — recoupements officiels du closing et du périmètre — organisme : Opella / Sanofi — document : Communiqué Day One et Annual Report on Form 20-F 2024 — publication : 2025-04-30 — date de valeur 2025-04-30, consultée le 2026-07-29 — périmètre : Closing ; périmètre de reporting et périmètre juridique transféré — localisation : Day One p. 1 ; Form 20-F pp. 32–33, p. 60 et note D.35 pp. F-94–F-95 — statut : recoupement public / cross-check — fait utilisé : Recoupement du closing, de l’actionnariat et des limites de comparabilité ; aucune valeur autonome du modèle — référence exacte : Opella — Opella devient indépendante pour redéfinir l’avenir de la santé du quotidien — publié le 2025-04-30 — Page 1, paragraphe d’ouverture — https://www.opella.com/dam/jcr%3A85e538d4-c944-4d64-9298-95fb4882b01e/20250430_Opella_Day%201%20PR_FR.pdf — consultée le 2026-07-29 ; Sanofi — Annual Report on Form 20-F 2024 — publié le 2025-02-13 — Pages 32–33, page 60 et note D.35, pages F-94–F-95 — https://www.sanofi.com/assets/dotcom/content-app/publications/annual-report-on-form-20-f/2024-01-01-form-20-f-2024-en.pdf — consultée le 2026-07-29
B18: S4 | C18: Modèle Opella — hypothèses illustratives — organisme : Modèle Opella — document : Hypothèses illustratives du générateur canonique — publication : 2026-07-08 — date de valeur 2026-07-08, consultée le 2026-07-29 — périmètre : Scénario illustratif P0–P5 — localisation : Transaction Services/build_carveout.py — paramètres M1 à M7 — statut : estimation / internal — fait utilisé : Trajectoire, allocations, coûts stand-alone, TSA, one-offs, bridge cash et contrefactuel ; aucune publication externe — référence exacte : Modèle Opella — Hypothèses internes portées par le générateur canonique — publié le 2026-07-08 — Paramètres M1 à M7 — Transaction Services/build_carveout.py — consultée le 2026-07-29
B19: S5 | C19: Sanofi — résultats FY2024 — organisme : Sanofi — document : Q4 and FY 2024 financial results — publication : 2025-01-30 — date de valeur 2024-12-31, consultée le 2026-07-29 — périmètre : FY2024 ; nouveau périmètre de reporting — localisation : Page 10, paragraphe « Opella » — statut : public / primary — fait utilisé : Chiffre d’affaires Opella FY2024 de 4 948 M€ selon le nouveau périmètre de reporting — référence exacte : Sanofi — Q4 and FY 2024 financial results — publié le 2025-01-30 — Page 10, paragraphe « Opella » — https://www.sanofi.com/assets/dotcom/pressreleases/2025/2025-01-30-06-30-00-3017713-en.pdf — consultée le 2026-07-29
B20: S6 | C20: Opella — périmètre opérationnel et marques — organisme : Opella — document : Official Opella evidence bundle — operational footprint and brands — publication : not-stated — date de valeur 2026-08-11, consultée le 2026-08-11 — périmètre : Périmètre opérationnel et portefeuille de marques au 11/08/2026 — localisation : Investors — “Who we are” and “Key figures”; Meet Opella — “Our leaders” > “Rafik Amrane”; 7 July 2026 press release — “About Opella” — statut : public / primary — fait utilisé : Environ 100 marques ; 500 millions de consommateurs ; 11 000+ salariés ; 90+ nationalités ; 38 pays en direct ; environ 110 pays servis indirectement ; 13 sites industriels ; 4 centres spécialisés ; 5 000+ professionnels Manufacturing & Supply ; marques Allegra, Buscopan, Doliprane, Dulcolax, Enterogermina, Essentiale et Mucosolvan — référence exacte : Opella — Investors — Key figures — publié le not-stated — Sections “Who we are” and “Key figures” — https://www.opella.com/en/investors — consultée le 2026-08-11 ; Opella — Meet Opella — publié le not-stated — Section “Our leaders”, profile “Rafik Amrane” — https://www.opella.com/en/meet-opella — consultée le 2026-08-11 ; Opella — Experts call for earlier recognition of fatty liver disease in people living with obesity — publié le 2026-07-07 — Section “About Opella”, second paragraph — https://www.opella.com/en/making-headlines/breaking-news/2026-essentiale-economics-obesity-metabolic-health-summit — consultée le 2026-08-11
B22: FILIATION SOURCE → HYPOTHÈSE/CELLULE → FORMULE → OUTPUT
B23: Id | C23: Hypothèses / cellules | D23: Formules | E23: Outputs | F23: Sources
B24: LN-L-EBITDA | C24: m1.revenue = Hypothèses!C6 ; m1.margin = Hypothèses!C8 | D24: R-PERIM | E24: m1.ebitda @ Hypothèses!C9 ; m7.inventory[L-EBITDA] @ 'M6 Bridge'!H6 | F24: S1, S4, S5
B25: LN-ENTRY-MULTIPLE | C25: m1.enterpriseValue = Hypothèses!C10 ; m1.ebitda = Hypothèses!C9 | D25: R-MULT | E25: m1.entryMultiple @ Hypothèses!C11 | F25: S1
B26: LN-OWNERSHIP | C26: m1.ownership.cdr = Hypothèses!C12 ; m1.ownership.sanofi = Hypothèses!C13 ; m1.ownership.bpifrance = Hypothèses!C14 | D26: R-OWN | E26: m1.ownership.total @ Hypothèses!C15 | F26: S2
B27: LN-O-RUNRATE | C27: m3.functions[F-IT].runRate = 'M3 Stand-alone'!C11 ; m3.functions[F-SUP].runRate = 'M3 Stand-alone'!C12 ; m3.functions[F-DIS].runRate = 'M3 Stand-alone'!C13 ; m3.functions[F-QUA].runRate = 'M3 Stand-alone'!C14 | D27: R-RAMP, R-STANDALONE | E27: outputs.O-RUNRATE @ 'M3 Stand-alone'!C15 | F27: S4
B28: LN-O-SEPCOST | C28: m4.services[T-IT].monthly = 'M4 TSA'!C6 ; m4.services[T-SC].monthly = 'M4 TSA'!C7 ; m4.services[T-FIN].monthly = 'M4 TSA'!C8 ; m4.services[T-REG].monthly = 'M4 TSA'!C9 ; m4.services[T-OTH].monthly = 'M4 TSA'!C10 ; m5.lines[O-IT].P1 = 'M5 One-offs'!D6 ; m5.lines[O-IT].P2 = 'M5 One-offs'!E6 ; m5.lines[O-IT].P3 = 'M5 One-offs'!F6 ; m5.lines[O-IT].P4 = 'M5 One-offs'!G6 ; m5.lines[O-IT].P5 = 'M5 One-offs'!H6 ; m5.lines[O-LEG].P1 = 'M5 One-offs'!D7 ; m5.lines[O-LEG].P2 = 'M5 One-offs'!E7 ; m5.lines[O-LEG].P3 = 'M5 One-offs'!F7 ; m5.lines[O-LEG].P4 = 'M5 One-offs'!G7 ; m5.lines[O-LEG].P5 = 'M5 One-offs'!H7 ; m5.lines[O-BRD].P1 = 'M5 One-offs'!D8 ; m5.lines[O-BRD].P2 = 'M5 One-offs'!E8 ; m5.lines[O-BRD].P3 = 'M5 One-offs'!F8 ; m5.lines[O-BRD].P4 = 'M5 One-offs'!G8 ; m5.lines[O-BRD].P5 = 'M5 One-offs'!H8 ; m5.lines[O-HR].P1 = 'M5 One-offs'!D9 ; m5.lines[O-HR].P2 = 'M5 One-offs'!E9 ; m5.lines[O-HR].P3 = 'M5 One-offs'!F9 ; m5.lines[O-HR].P4 = 'M5 One-offs'!G9 ; m5.lines[O-HR].P5 = 'M5 One-offs'!H9 ; m5.lines[O-SC].P1 = 'M5 One-offs'!D10 ; m5.lines[O-SC].P2 = 'M5 One-offs'!E10 ; m5.lines[O-SC].P3 = 'M5 One-offs'!F10 ; m5.lines[O-SC].P4 = 'M5 One-offs'!G10 ; m5.lines[O-SC].P5 = 'M5 One-offs'!H10 ; m5.lines[O-ADV].P1 = 'M5 One-offs'!D11 ; m5.lines[O-ADV].P2 = 'M5 One-offs'!E11 ; m5.lines[O-ADV].P3 = 'M5 One-offs'!F11 ; m5.lines[O-ADV].P4 = 'M5 One-offs'!G11 ; m5.lines[O-ADV].P5 = 'M5 One-offs'!H11 ; m6.L-SEPCAPEX.P1 = 'M6 Bridge'!D23 ; m6.L-SEPCAPEX.P2 = 'M6 Bridge'!E23 ; m6.L-SEPCAPEX.P3 = 'M6 Bridge'!F23 ; m6.L-SEPCAPEX.P4 = 'M6 Bridge'!G23 ; m6.L-SEPCAPEX.P5 = 'M6 Bridge'!H23 | D28: R-TSA-SUM, R-ONEOFF-SUM, R-SEPCOST | E28: outputs.O-SEPCOST @ 'M6 Bridge'!C34 | F28: S4
B29: LN-O-PEAK | C29: m6.cash.P1 = 'M6 Bridge'!D31 ; m6.cash.P2 = 'M6 Bridge'!E31 ; m6.cash.P3 = 'M6 Bridge'!F31 ; m6.cash.P4 = 'M6 Bridge'!G31 ; m6.cash.P5 = 'M6 Bridge'!H31 ; m7.counterfactual.cash.P1 = 'M7 Financement'!C15 ; m7.counterfactual.cash.P2 = 'M7 Financement'!D15 ; m7.counterfactual.cash.P3 = 'M7 Financement'!E15 ; m7.counterfactual.cash.P4 = 'M7 Financement'!F15 ; m7.counterfactual.cash.P5 = 'M7 Financement'!G15 | D29: R-CASH, R-CF, R-FUNDING-CUM, R-PEAK | E29: outputs.O-PEAK.value @ 'M7 Financement'!C71 ; outputs.O-PEAK.period @ 'M7 Financement'!C72 | F29: S4
B30: LN-O-STEADY | C30: m3.functions[F-IT].ramp.P1 = 'M3 Stand-alone'!E6 ; m3.functions[F-IT].ramp.P2 = 'M3 Stand-alone'!F6 ; m3.functions[F-IT].ramp.P3 = 'M3 Stand-alone'!G6 ; m3.functions[F-IT].ramp.P4 = 'M3 Stand-alone'!H6 ; m3.functions[F-IT].ramp.P5 = 'M3 Stand-alone'!I6 ; m3.functions[F-SUP].ramp.P1 = 'M3 Stand-alone'!E7 ; m3.functions[F-SUP].ramp.P2 = 'M3 Stand-alone'!F7 ; m3.functions[F-SUP].ramp.P3 = 'M3 Stand-alone'!G7 ; m3.functions[F-SUP].ramp.P4 = 'M3 Stand-alone'!H7 ; m3.functions[F-SUP].ramp.P5 = 'M3 Stand-alone'!I7 ; m3.functions[F-DIS].ramp.P1 = 'M3 Stand-alone'!E8 ; m3.functions[F-DIS].ramp.P2 = 'M3 Stand-alone'!F8 ; m3.functions[F-DIS].ramp.P3 = 'M3 Stand-alone'!G8 ; m3.functions[F-DIS].ramp.P4 = 'M3 Stand-alone'!H8 ; m3.functions[F-DIS].ramp.P5 = 'M3 Stand-alone'!I8 ; m3.functions[F-QUA].ramp.P1 = 'M3 Stand-alone'!E9 ; m3.functions[F-QUA].ramp.P2 = 'M3 Stand-alone'!F9 ; m3.functions[F-QUA].ramp.P3 = 'M3 Stand-alone'!G9 ; m3.functions[F-QUA].ramp.P4 = 'M3 Stand-alone'!H9 ; m3.functions[F-QUA].ramp.P5 = 'M3 Stand-alone'!I9 ; m4.byPeriod.P1 = 'M4 TSA'!J11 ; m4.byPeriod.P2 = 'M4 TSA'!K11 ; m4.byPeriod.P3 = 'M4 TSA'!L11 ; m4.byPeriod.P4 = 'M4 TSA'!M11 ; m4.byPeriod.P5 = 'M4 TSA'!N11 ; m5.byPeriod.P1 = 'M5 One-offs'!D12 ; m5.byPeriod.P2 = 'M5 One-offs'!E12 ; m5.byPeriod.P3 = 'M5 One-offs'!F12 ; m5.byPeriod.P4 = 'M5 One-offs'!G12 ; m5.byPeriod.P5 = 'M5 One-offs'!H12 | D30: R-RAMP, R-TSA-SUM, R-ONEOFF-SUM, R-STEADY | E30: outputs.O-STEADY @ Calendrier!C14 | F30: S4
B31: LN-O-RESORB | C31: m7.periods[P5].need = 'M7 Financement'!G64 ; m7.periods[P5].eGap = 'M7 Financement'!G38 ; m7.periods[P5].nOneOff = 'M7 Financement'!G56 ; m7.horizon.delta = 'M7 Financement'!C74 | D31: R-EGAP, R-NPONC, R-RECUR, R-RESORB, R-PK | E31: outputs.O-RESORB.state @ 'M7 Financement'!C76 | F31: S4

Sheet Calendrier
B2: CALENDRIER ET CONVENTIONS DE PÉRIODE (§4)
B4: Période | C4: Libellé | D4: Début | E4: Fin | F4: Mois | G4: Rôle
B5: P0 | C5: FY2024 | D5: 2024-01-01 | E5: 2024-12-31 | F5: 12 | G5: base vendeur, avant séparation
B6: P1 | C6: Mai–déc. 2025 | D6: 2025-05-01 | E6: 2025-12-31 | F6: 8 | G6: stub post-closing
B7: P2 | C7: FY2026 | D7: 2026-01-01 | E7: 2026-12-31 | F7: 12 | G7: transition
B8: P3 | C8: FY2027 | D8: 2027-01-01 | E8: 2027-12-31 | F8: 12 | G8: première année candidate au régime établi
B9: P4 | C9: FY2028 | D9: 2028-01-01 | E9: 2028-12-31 | F9: 12 | G9: année civile ouverte par la règle 4 du §4
B10: P5 | C10: FY2029 | D10: 2029-01-01 | E10: 2029-12-31 | F10: 12 | G10: année civile ouverte par la règle 4 du §4
B12: Closing | C12: 2025-04-30
B13: maxHorizon | C13: P5 | G13: dernière période modélisée : régime établi + une période de confirmation (§4, règle 4)
B14: Régime établi | C14: P4 | G14: output daté : première période sans TSA, sans one-off, à run-rate plein (§4, règle 3)
B17: CONVERSION DES MOIS CONTRACTUELS DE TSA (§4, règle 2)
B18: Service | C18: Durée (mois) | D18: P1 | E18: P2 | F18: P3 | G18: P4 | H18: P5 | I18: Somme des mois | J18: Écart R-TSA-CAL
B19: IT (ERP, infrastructure, support) | C19: 24 | D19: 8 | E19: 12 | F19: 4 | G19: 0 | H19: 0 | I19: =SUM(D19:H19) -> 24 | J19: =I19-C19 -> 0
B20: Supply chain et logistique | C20: 18 | D20: 8 | E20: 10 | F20: 0 | G20: 0 | H20: 0 | I20: =SUM(D20:H20) -> 18 | J20: =I20-C20 -> 0
B21: Finance (comptabilité, paie, fiscalité) | C21: 12 | D21: 8 | E21: 4 | F21: 0 | G21: 0 | H21: 0 | I21: =SUM(D21:H21) -> 12 | J21: =I21-C21 -> 0
B22: Réglementaire et pharmacovigilance | C22: 24 | D22: 8 | E22: 12 | F22: 4 | G22: 0 | H22: 0 | I22: =SUM(D22:H22) -> 24 | J22: =I22-C22 -> 0
B23: Autres (immobilier, achats) | C23: 12 | D23: 8 | E23: 4 | F23: 0 | G23: 0 | H23: 0 | I23: =SUM(D23:H23) -> 12 | J23: =I23-C23 -> 0

Sheet Hypothèses
B2: HYPOTHÈSES ET ANCRAGES
B4: Poste | C4: Valeur | D4: Statut | E4: Source | F4: Driver et justification
B5: M1 — Périmètre et ancrages
B6: Chiffre d'affaires FY2024 publié retenu par le modèle (M€) | C6: 4948 | D6: public | E6: S5 | F6: CA de 4 948 M€ publié par Sanofi selon son nouveau périmètre de reporting
B7: Chiffre d'affaires FY2024 publié par Sanofi (M€) | C7: 4948 | D7: public | E7: S5 | F7: résultats FY2024 Sanofi, p. 10, nouveau périmètre de reporting
B8: Marge d'EBITDA implicite du modèle | C8: =C9/C6 -> 0.23097355 | D8: calculé | E8: S1+S5 | F8: proxy EBITDA implicite ÷ CA FY2024 publié ; cette marge n'est pas publiée
B9: EBITDA 2024E implicite de transaction (M€) | C9: =C10/14 -> 1142.8571 | D9: calculé | E9: S1 | F9: proxy implicite des ancrages publics ≈16 Md€ / ≈14x ; montant non publié séparément
B10: Valeur d'entreprise de la transaction (M€) | C10: 16000 | D10: public | E10: S1 | F10: communiqué Sanofi du 21/10/2024 — valeur d'entreprise d'environ 16 Md€
B11: Multiple d'EBITDA estimé 2024 annoncé | C11: =C10/C9 -> 14 | D11: public | E11: S1 | F11: Sanofi annonce environ 14x ; R-MULT réconcilie EV ÷ EBITDA implicite sans changer le moteur
B12: Participation CD&R | C12: 0.5 | D12: public | E12: S2 | F12: communiqué de closing du 30/04/2025
B13: Participation Sanofi (conservée) | C13: 0.482 | D13: public | E13: S2 | F13: communiqué de closing du 30/04/2025
B14: Participation Bpifrance | C14: 0.018 | D14: public | E14: S2 | F14: communiqué de closing du 30/04/2025
B15: Somme des participations | C15: =SUM(C12:C14) -> 1 | D15: calculé | E15: S2 | F15: R-OWN : doit valoir 100 %
B17: Trajectoire opérationnelle
B18: Croissance annuelle du CA | C18: 0.03 | D18: estimation | E18: S4 | F18: croissance du marché CHC ; piloté par le levier S-OPS
B19: Expansion de marge (pts par an) | C19: 0.003 | D19: estimation | E19: S4 | F19: mix et pricing ; piloté par le levier S-OPS
B21: M2 — Allocations vendeur
B22: Allocations vendeur réintégrées (part du CA) | C22: 0.016 | D22: estimation | E22: S4 | F22: les coûts de siège alloués par Sanofi cessent au closing ; driver déclaré : le CA
B24: M6 — Paramètres du bridge EBITDA → cash
B25: Taux d'impôt cash effectif | C25: 0.22 | D25: estimation | E25: S4 | F25: proxy après amortissements ; appliqué séparément à la base récurrente et aux coûts de séparation
B26: Capex courant (part du CA) | C26: 0.025 | D26: estimation | E26: S4 | F26: capex d'exploitation, distinct du capex de séparation
B27: BFR courant (part du CA incrémental) | C27: 0.15 | D27: estimation | E27: S4 | F27: besoin en fonds de roulement absorbé par la croissance
B28: Autres éléments cash déclarés (par période, M€) | C28: 0 | D28: à confirmer | E28: S4 | F28: poste déclaré nul en base ; entrée de diligence ouverte (§12)
B29: Surcoût du mois de TSA prolongé | C29: 0.2 | D29: estimation | E29: S4 | F29: prolongation traitée comme un levier de scénario, jamais comme une hypothèse de base

Sheet M3 Stand-alone
B2: M3 — COÛTS STAND-ALONE RÉCURRENTS PAR FONCTION (M€)
B3: Coût appliqué = run-rate × taux de montée en charge de la période, borné à [0 ; 1] (R-RAMP). Aucun coût récurrent n'est appliqué à P0.
B5: Fonction | C5: Run-rate cible | D5: P0 | E5: P1 | F5: P2 | G5: P3 | H5: P4 | I5: P5 | J5: Driver
B6: IT et infrastructure — montée en charge | D6: 0 | E6: 0.25 | F6: 0.7 | G6: 1 | H6: 1 | I6: 1 | J6: ERP, licences, hébergement, cybersécurité en propre
B7: Fonctions support (finance, RH, juridique) — montée en charge | D7: 0 | E7: 0.4 | F7: 0.85 | G7: 1 | H7: 1 | I7: 1 | J7: équipes siège à recréer, sortie des centres de services Sanofi
B8: Distribution et achats — montée en charge | D8: 0 | E8: 0.5 | F8: 1 | G8: 1 | H8: 1 | I8: 1 | J8: perte de mutualisation des contrats groupe
B9: Qualité, réglementaire, pharmacovigilance — montée en charge | D9: 0 | E9: 0.45 | F9: 0.9 | G9: 1 | H9: 1 | I9: 1 | J9: licences et équipes dédiées imposées par la réglementation
B11: Coûts stand-alone — IT et infrastructure | C11: -40 | D11: =$C11*D6 -> 0 | E11: =$C11*E6 -> -10 | F11: =$C11*F6 -> -28 | G11: =$C11*G6 -> -40 | H11: =$C11*H6 -> -40 | I11: =$C11*I6 -> -40
B12: Coûts stand-alone — Fonctions support (finance, RH, juridique) | C12: -30 | D12: =$C12*D7 -> 0 | E12: =$C12*E7 -> -12 | F12: =$C12*F7 -> -25.5 | G12: =$C12*G7 -> -30 | H12: =$C12*H7 -> -30 | I12: =$C12*I7 -> -30
B13: Coûts stand-alone — Distribution et achats | C13: -25 | D13: =$C13*D8 -> 0 | E13: =$C13*E8 -> -12.5 | F13: =$C13*F8 -> -25 | G13: =$C13*G8 -> -25 | H13: =$C13*H8 -> -25 | I13: =$C13*I8 -> -25
B14: Coûts stand-alone — Qualité, réglementaire, pharmacovigilance | C14: -25 | D14: =$C14*D9 -> 0 | E14: =$C14*E9 -> -11.25 | F14: =$C14*F9 -> -22.5 | G14: =$C14*G9 -> -25 | H14: =$C14*H9 -> -25 | I14: =$C14*I9 -> -25
B15: Total coûts stand-alone appliqués | C15: =SUM(C11:C14) -> -120 | D15: =SUM(D11:D14) -> 0 | E15: =SUM(E11:E14) -> -45.75 | F15: =SUM(F11:F14) -> -101 | G15: =SUM(G11:G14) -> -120 | H15: =SUM(H11:H14) -> -120 | I15: =SUM(I11:I14) -> -120

Sheet M4 TSA
B2: M4 — TSA PAR SERVICE (M€ et mois contractuels)
B3: Le mois 1 est mai 2025. La fenêtre de double run est la période où le service TSA et la capacité interne qui le remplace tournent ensemble ; elle est datée, jamais implicite.
B5: Service | C5: Coût mensuel | D5: Début (mois) | E5: Durée contractuelle | F5: Sortie prévue (mois) | G5: Prolongation dispo. | H5: Double run (mois) | I5: P0 | J5: P1 | K5: P2 | L5: P3 | M5: P4 | N5: P5 | O5: Stratégie de sortie
B6: IT (ERP, infrastructure, support) | C6: -2.1 | D6: 1 | E6: 24 | F6: =D6+E6-1 -> 24 | G6: 12 | H6: =MAX(0,E6-19+1) -> 6 | I6: 0 | J6: -16.8 | K6: -25.2 | L6: -8.4 | M6: 0 | N6: 0 | O6: ERP en propre puis infogérance
B7: Supply chain et logistique | C7: -1.25 | D7: 1 | E7: 18 | F7: =D7+E7-1 -> 18 | G7: 6 | H7: =MAX(0,E7-15+1) -> 4 | I7: 0 | J7: -10 | K7: -12.5 | L7: 0 | M7: 0 | N7: 0 | O7: reprise des contrats 3PL en direct
B8: Finance (comptabilité, paie, fiscalité) | C8: -0.85 | D8: 1 | E8: 12 | F8: =D8+E8-1 -> 12 | G8: 6 | H8: =MAX(0,E8-10+1) -> 3 | I8: 0 | J8: -6.8 | K8: -3.4 | L8: 0 | M8: 0 | N8: 0 | O8: internalisation et centre de services
B9: Réglementaire et pharmacovigilance | C9: -0.5 | D9: 1 | E9: 24 | F9: =D9+E9-1 -> 24 | G9: 12 | H9: =MAX(0,E9-21+1) -> 4 | I9: 0 | J9: -4 | K9: -6 | L9: -2 | M9: 0 | N9: 0 | O9: équipes dédiées, contrainte de licences
B10: Autres (immobilier, achats) | C10: -0.3 | D10: 1 | E10: 12 | F10: =D10+E10-1 -> 12 | G10: 6 | H10: =MAX(0,E10-12+1) -> 1 | I10: 0 | J10: -2.4 | K10: -1.2 | L10: 0 | M10: 0 | N10: 0 | O10: baux directs et contrats cadres propres
B11: Total TSA | I11: =SUM(I6:I10) -> 0 | J11: =SUM(J6:J10) -> -40 | K11: =SUM(K6:K10) -> -48.3 | L11: =SUM(L6:L10) -> -10.4 | M11: =SUM(M6:M10) -> 0 | N11: =SUM(N6:N10) -> 0

Sheet M5 One-offs
B2: M5 — ONE-OFFS PAR NATURE ET PAR PÉRIODE (M€)
B3: Une ligne par nature et par période d'engagement. Aucun forfait global réparti par pourcentage.
B5: Nature | C5: P0 | D5: P1 | E5: P2 | F5: P3 | G5: P4 | H5: P5 | I5: Total | J5: Statut
B6: Séparation IT (migration ERP, données, réseaux) | C6: 0 | D6: -24 | E6: -34 | F6: 0 | G6: 0 | H6: 0 | I6: =SUM(C6:H6) -> -58 | J6: estimation
B7: Mise en place des entités juridiques | C7: 0 | D7: -12 | E7: -6 | F7: 0 | G7: 0 | H7: 0 | I7: =SUM(C7:H7) -> -18 | J7: estimation
B8: Marque et packaging (rebranding) | C8: 0 | D8: -14 | E8: -16 | F8: -4 | G8: 0 | H8: 0 | I8: =SUM(C8:H8) -> -34 | J8: estimation
B9: Ressources humaines (transferts, rétention) | C9: 0 | D9: -9 | E9: -7 | F9: 0 | G9: 0 | H9: 0 | I9: =SUM(C9:H9) -> -16 | J9: estimation
B10: Requalification supply chain (sites, licences) | C10: 0 | D10: -4 | E10: -7 | F10: -3 | G10: 0 | H10: 0 | I10: =SUM(C10:H10) -> -14 | J10: estimation
B11: Conseils (juridique, financier, intégration) | C11: 0 | D11: -8 | E11: -4 | F11: 0 | G11: 0 | H11: 0 | I11: =SUM(C11:H11) -> -12 | J11: à confirmer
B12: Total one-offs | C12: =SUM(C6:C11) -> 0 | D12: =SUM(D6:D11) -> -71 | E12: =SUM(E6:E11) -> -74 | F12: =SUM(F6:F11) -> -7 | G12: =SUM(G6:G11) -> 0 | H12: =SUM(H6:H11) -> 0 | I12: =SUM(I6:I11) -> -152

Sheet M6 Bridge
B2: M6 — BRIDGE EBITDA → CASH, PAR PÉRIODE (M€, registre comptable)
B3: Chaque ligne porte sa convention de signe : une charge est négative. Les métadonnées de droite font de chaque ligne un élément qualifiable de l'inventaire du §6.1.2.
B5: Ligne du bridge | C5: P0 | D5: P1 | E5: P2 | F5: P3 | G5: P4 | H5: P5 | I5: Module | J5: Groupe | K5: Côté | L5: Qualification | M5: Début | N5: Fin décl. | O5: L-REC | P5: Driver | Q5: Source | R5: Statut
B6: EBITDA périmètre (tel qu'alloué par le vendeur) | C6: 1142.8571 | D6: 794.95478 | E6: 1243.9531 | F6: 1297.4922 | G6: 1353.124 | H6: 1410.926 | I6: M1 | J6: L-M6OTH | K6: cas | L6: récurrent | M6: P1 | N6: — | O6: — | P6: CA de la période × marge périmètre ; deux hypothèses S4, non publiées par S1 | Q6: S4 | R6: calculé
B7: Allocations vendeur réintégrées | C7: 0 | D7: 54.362027 | E7: 83.989331 | F7: 86.509011 | G7: 89.104281 | H7: 91.77741 | I7: M2 | J7: L-M6OTH | K7: cas | L7: récurrent | M7: P1 | N7: — | O7: — | P7: 1.60% du CA de la période | Q7: S4 | R7: estimation
B8: Coûts stand-alone — IT et infrastructure | C8: ='M3 Stand-alone'!D11 -> 0 | D8: ='M3 Stand-alone'!E11 -> -10 | E8: ='M3 Stand-alone'!F11 -> -28 | F8: ='M3 Stand-alone'!G11 -> -40 | G8: ='M3 Stand-alone'!H11 -> -40 | H8: ='M3 Stand-alone'!I11 -> -40 | I8: M3 | J8: L-M3 | K8: cas | L8: récurrent | M8: P1 | N8: — | O8: — | P8: ERP, licences, hébergement, cybersécurité en propre | Q8: S4 | R8: estimation
B9: Coûts stand-alone — Fonctions support (finance, RH, juridique) | C9: ='M3 Stand-alone'!D12 -> 0 | D9: ='M3 Stand-alone'!E12 -> -12 | E9: ='M3 Stand-alone'!F12 -> -25.5 | F9: ='M3 Stand-alone'!G12 -> -30 | G9: ='M3 Stand-alone'!H12 -> -30 | H9: ='M3 Stand-alone'!I12 -> -30 | I9: M3 | J9: L-M3 | K9: cas | L9: récurrent | M9: P1 | N9: — | O9: — | P9: équipes siège à recréer, sortie des centres de services Sanofi | Q9: S4 | R9: estimation
B10: Coûts stand-alone — Distribution et achats | C10: ='M3 Stand-alone'!D13 -> 0 | D10: ='M3 Stand-alone'!E13 -> -12.5 | E10: ='M3 Stand-alone'!F13 -> -25 | F10: ='M3 Stand-alone'!G13 -> -25 | G10: ='M3 Stand-alone'!H13 -> -25 | H10: ='M3 Stand-alone'!I13 -> -25 | I10: M3 | J10: L-M3 | K10: cas | L10: récurrent | M10: P1 | N10: — | O10: — | P10: perte de mutualisation des contrats groupe | Q10: S4 | R10: estimation
B11: Coûts stand-alone — Qualité, réglementaire, pharmacovigilance | C11: ='M3 Stand-alone'!D14 -> 0 | D11: ='M3 Stand-alone'!E14 -> -11.25 | E11: ='M3 Stand-alone'!F14 -> -22.5 | F11: ='M3 Stand-alone'!G14 -> -25 | G11: ='M3 Stand-alone'!H14 -> -25 | H11: ='M3 Stand-alone'!I14 -> -25 | I11: M3 | J11: L-M3 | K11: cas | L11: récurrent | M11: P1 | N11: — | O11: — | P11: licences et équipes dédiées imposées par la réglementation | Q11: S4 | R11: estimation
B12: TSA — IT (ERP, infrastructure, support) | C12: ='M4 TSA'!I6 -> 0 | D12: ='M4 TSA'!J6 -> -16.8 | E12: ='M4 TSA'!K6 -> -25.2 | F12: ='M4 TSA'!L6 -> -8.4 | G12: ='M4 TSA'!M6 -> 0 | H12: ='M4 TSA'!N6 -> 0 | I12: M4 | J12: L-M4 | K12: cas | L12: ponctuel | M12: P1 | N12: P3 | O12: — | P12: 2.10 M€/mois × mois contractuels affectés | Q12: S4 | R12: estimation
B13: TSA — Supply chain et logistique | C13: ='M4 TSA'!I7 -> 0 | D13: ='M4 TSA'!J7 -> -10 | E13: ='M4 TSA'!K7 -> -12.5 | F13: ='M4 TSA'!L7 -> 0 | G13: ='M4 TSA'!M7 -> 0 | H13: ='M4 TSA'!N7 -> 0 | I13: M4 | J13: L-M4 | K13: cas | L13: ponctuel | M13: P1 | N13: P2 | O13: — | P13: 1.25 M€/mois × mois contractuels affectés | Q13: S4 | R13: estimation
B14: TSA — Finance (comptabilité, paie, fiscalité) | C14: ='M4 TSA'!I8 -> 0 | D14: ='M4 TSA'!J8 -> -6.8 | E14: ='M4 TSA'!K8 -> -3.4 | F14: ='M4 TSA'!L8 -> 0 | G14: ='M4 TSA'!M8 -> 0 | H14: ='M4 TSA'!N8 -> 0 | I14: M4 | J14: L-M4 | K14: cas | L14: ponctuel | M14: P1 | N14: P2 | O14: — | P14: 0.85 M€/mois × mois contractuels affectés | Q14: S4 | R14: estimation
B15: TSA — Réglementaire et pharmacovigilance | C15: ='M4 TSA'!I9 -> 0 | D15: ='M4 TSA'!J9 -> -4 | E15: ='M4 TSA'!K9 -> -6 | F15: ='M4 TSA'!L9 -> -2 | G15: ='M4 TSA'!M9 -> 0 | H15: ='M4 TSA'!N9 -> 0 | I15: M4 | J15: L-M4 | K15: cas | L15: ponctuel | M15: P1 | N15: P3 | O15: — | P15: 0.50 M€/mois × mois contractuels affectés | Q15: S4 | R15: estimation
B16: TSA — Autres (immobilier, achats) | C16: ='M4 TSA'!I10 -> 0 | D16: ='M4 TSA'!J10 -> -2.4 | E16: ='M4 TSA'!K10 -> -1.2 | F16: ='M4 TSA'!L10 -> 0 | G16: ='M4 TSA'!M10 -> 0 | H16: ='M4 TSA'!N10 -> 0 | I16: M4 | J16: L-M4 | K16: cas | L16: ponctuel | M16: P1 | N16: P2 | O16: — | P16: 0.30 M€/mois × mois contractuels affectés | Q16: S4 | R16: estimation
B17: One-off — Séparation IT (migration ERP, données, réseaux) | C17: ='M5 One-offs'!C6 -> 0 | D17: ='M5 One-offs'!D6 -> -24 | E17: ='M5 One-offs'!E6 -> -34 | F17: ='M5 One-offs'!F6 -> 0 | G17: ='M5 One-offs'!G6 -> 0 | H17: ='M5 One-offs'!H6 -> 0 | I17: M5 | J17: L-M5 | K17: cas | L17: ponctuel | M17: P1 | N17: P2 | O17: — | P17: montant engagé sur la période | Q17: S4 | R17: estimation
B18: One-off — Mise en place des entités juridiques | C18: ='M5 One-offs'!C7 -> 0 | D18: ='M5 One-offs'!D7 -> -12 | E18: ='M5 One-offs'!E7 -> -6 | F18: ='M5 One-offs'!F7 -> 0 | G18: ='M5 One-offs'!G7 -> 0 | H18: ='M5 One-offs'!H7 -> 0 | I18: M5 | J18: L-M5 | K18: cas | L18: ponctuel | M18: P1 | N18: P2 | O18: — | P18: montant engagé sur la période | Q18: S4 | R18: estimation
B19: One-off — Marque et packaging (rebranding) | C19: ='M5 One-offs'!C8 -> 0 | D19: ='M5 One-offs'!D8 -> -14 | E19: ='M5 One-offs'!E8 -> -16 | F19: ='M5 One-offs'!F8 -> -4 | G19: ='M5 One-offs'!G8 -> 0 | H19: ='M5 One-offs'!H8 -> 0 | I19: M5 | J19: L-M5 | K19: cas | L19: ponctuel | M19: P1 | N19: P3 | O19: — | P19: montant engagé sur la période | Q19: S4 | R19: estimation
B20: One-off — Ressources humaines (transferts, rétention) | C20: ='M5 One-offs'!C9 -> 0 | D20: ='M5 One-offs'!D9 -> -9 | E20: ='M5 One-offs'!E9 -> -7 | F20: ='M5 One-offs'!F9 -> 0 | G20: ='M5 One-offs'!G9 -> 0 | H20: ='M5 One-offs'!H9 -> 0 | I20: M5 | J20: L-M5 | K20: cas | L20: ponctuel | M20: P1 | N20: P2 | O20: — | P20: montant engagé sur la période | Q20: S4 | R20: estimation
B21: One-off — Requalification supply chain (sites, licences) | C21: ='M5 One-offs'!C10 -> 0 | D21: ='M5 One-offs'!D10 -> -4 | E21: ='M5 One-offs'!E10 -> -7 | F21: ='M5 One-offs'!F10 -> -3 | G21: ='M5 One-offs'!G10 -> 0 | H21: ='M5 One-offs'!H10 -> 0 | I21: M5 | J21: L-M5 | K21: cas | L21: ponctuel | M21: P1 | N21: P3 | O21: — | P21: montant engagé sur la période | Q21: S4 | R21: estimation
B22: One-off — Conseils (juridique, financier, intégration) | C22: ='M5 One-offs'!C11 -> 0 | D22: ='M5 One-offs'!D11 -> -8 | E22: ='M5 One-offs'!E11 -> -4 | F22: ='M5 One-offs'!F11 -> 0 | G22: ='M5 One-offs'!G11 -> 0 | H22: ='M5 One-offs'!H11 -> 0 | I22: M5 | J22: L-M5 | K22: cas | L22: ponctuel | M22: P1 | N22: P2 | O22: — | P22: montant engagé sur la période | Q22: S4 | R22: à confirmer
B23: Capex de séparation | C23: 0 | D23: -20 | E23: -20 | F23: -5 | G23: 0 | H23: 0 | I23: M6 | J23: L-M6SEP | K23: cas | L23: ponctuel | M23: P1 | N23: P3 | O23: — | P23: investissements dédiés à la séparation, distincts du capex courant | Q23: S4 | R23: estimation
B24: BFR de séparation — constitution | C24: 0 | D24: -55 | E24: -10 | F24: 0 | G24: 0 | H24: 0 | I24: M6 | J24: L-M6SEP | K24: cas | L24: ponctuel | M24: P1 | N24: P2 | O24: — | P24: stocks de sécurité, décalage clients, perte des conditions groupe | Q24: S4 | R24: estimation
B25: BFR de séparation — reprise | C25: 0 | D25: 0 | E25: 0 | F25: 15 | G25: 50 | H25: 0 | I25: M6 | J25: L-M6SEP | K25: cas | L25: ponctuel | M25: P3 | N25: P4 | O25: oui | P25: normalisation des conditions de paiement et des stocks | Q25: S4 | R25: estimation
B26: Impôts — effet des postes récurrents | C26: -251.42857 | D26: -176.7847 | E26: -269.92734 | F26: -278.08026 | G26: -290.89022 | H26: -304.19475 | I26: M6 | J26: L-M6OTH | K26: cas | L26: récurrent | M26: P1 | N26: — | O26: — | P26: taux d'impôt cash effectif de 22% sur la base récurrente | Q26: S4 | R26: calculé
B27: Impôts — effet des coûts de séparation | C27: 0 | D27: 24.42 | E27: 26.906 | F27: 3.828 | G27: 0 | H27: 0 | I27: M6 | J27: L-M6OTH | K27: cas | L27: ponctuel | M27: P1 | N27: P3 | O27: — | P27: taux d'impôt cash effectif de 22% sur TSA et one-offs | Q27: S4 | R27: calculé
B28: Capex courant | C28: -123.7 | D28: -84.940667 | E28: -131.23333 | F28: -135.17033 | G28: -139.22544 | H28: -143.4022 | I28: M6 | J28: L-M6OTH | K28: cas | L28: récurrent | M28: P1 | N28: — | O28: — | P28: 2.5% du CA de la période | Q28: S4 | R28: estimation
B29: BFR courant | C29: 0 | D29: -14.844 | E29: -22.93398 | F29: -23.621999 | G29: -24.330659 | H29: -25.060579 | I29: M6 | J29: L-M6OTH | K29: cas | L29: récurrent | M29: P1 | N29: — | O29: — | P29: 15% du CA incrémental de la période | Q29: S4 | R29: estimation
B30: Autres éléments cash déclarés | C30: 0 | D30: 0 | E30: 0 | F30: 0 | G30: 0 | H30: 0 | I30: M6 | J30: L-M6OTH | K30: cas | L30: récurrent | M30: P1 | N30: — | O30: — | P30: poste déclaré nul en base ; entrée de diligence ouverte | Q30: S4 | R30: à confirmer
B31: Cash de la période (R-CASH) | C31: =SUM(C6:C30) -> 767.72857 | D31: =SUM(D6:D30) -> 365.41745 | E31: =SUM(E6:E30) -> 677.45382 | F31: =SUM(F6:F30) -> 823.5566 | G31: =SUM(G6:G30) -> 917.78196 | H31: =SUM(H6:H30) -> 910.04586
B33: EBITDA stand-alone en run-rate (R-STANDALONE) | C33: ='M6 Bridge'!H6+'M6 Bridge'!H7+'M3 Stand-alone'!C15 -> 1382.7034 | I33: EBITDA périmètre + allocations réintégrées + total des coûts par fonction de M3, à la borne
B34: O-SEPCOST — coût total de séparation (R-SEPCOST) | C34: =-('M4 TSA'!J11+'M5 One-offs'!D12+'M6 Bridge'!D23+'M4 TSA'!K11+'M5 One-offs'!E12+'M6 Bridge'!E23+'M4 TSA'!L11+'M5 One-offs'!F12+'M6 Bridge'!F23+'M4 TSA'!M11+'M5 One-offs'!G12+'M6 Bridge'!G23+'M4 TSA'!N11+'M5 One-offs'!H12+'M6 Bridge'!H23) -> 295.7 | I34: TSA + one-offs + capex de séparation sur tout l'horizon, publié en coût positif. Le BFR de séparation en est exclu : c'est un besoin de trésorerie temporaire, porté par O-PEAK (§6.2).

Sheet M7 Financement
B2: M7 — BESOIN DE FINANCEMENT DE SÉPARATION
B3: Le besoin est l'écart cumulé de cash entre la trajectoire avec séparation et le contrefactuel déclaré ci-dessous. Il est publié en montant positif : une ligne du cas contribue pour −montant, une ligne du contrefactuel pour +montant.
B6: CONTREFACTUEL DÉCLARÉ — SANS SÉPARATION (R-CF)
B7: Opella reste dans le périmètre du vendeur : les allocations corporate continuent d'être supportées, aucun coût stand-alone propre, aucune TSA, aucun one-off, aucun capex ni BFR de séparation. Même trajectoire de CA et de marge que le cas.
B9: Ligne du contrefactuel | C9: P1 | D9: P2 | E9: P3 | F9: P4 | G9: P5 | H9: Qualification | I9: Fin décl. | J9: Source | K9: Statut | L9: Driver
B10: EBITDA périmètre (maintien dans le groupe) | C10: 794.95478 | D10: 1243.9531 | E10: 1297.4922 | F10: 1353.124 | G10: 1410.926 | H10: récurrent | I10: — | J10: S4 | K10: calculé | L10: même trajectoire de CA et de marge que le cas
B11: Impôts (contrefactuel) | C11: -174.89005 | D11: -273.66969 | E11: -285.44828 | F11: -297.68728 | G11: -310.40372 | H11: récurrent | I11: — | J11: S4 | K11: calculé | L11: même taux effectif de 22%, base sans séparation
B12: Capex courant (contrefactuel) | C12: -84.940667 | D12: -131.23333 | E12: -135.17033 | F12: -139.22544 | G12: -143.4022 | H12: récurrent | I12: — | J12: S4 | K12: estimation | L12: capex courant inchangé par la séparation
B13: BFR courant (contrefactuel) | C13: -14.844 | D13: -22.93398 | E13: -23.621999 | F13: -24.330659 | G13: -25.060579 | H13: récurrent | I13: — | J13: S4 | K13: estimation | L13: BFR d'exploitation inchangé par la séparation
B14: Autres éléments cash déclarés (contrefactuel) | C14: 0 | D14: 0 | E14: 0 | F14: 0 | G14: 0 | H14: récurrent | I14: — | J14: S4 | K14: à confirmer | L14: miroir du poste déclaré du cas
B15: Cash du contrefactuel | C15: =SUM(C10:C14) -> 520.28007 | D15: =SUM(D10:D14) -> 816.11614 | E15: =SUM(E10:E14) -> 853.25157 | F15: =SUM(F10:F14) -> 891.88062 | G15: =SUM(G10:G14) -> 932.05948
B18: INVENTAIRE DES CONTRIBUTIONS AU FLUX DE BESOIN (§6.1.2)
B19: Contribution d'une ligne du cas : −montant. Contribution d'une ligne du contrefactuel : +montant. L'inventaire est exhaustif : s(Pt) = Σ L-CF(Pt) − Σ L-CASE(Pt).
B21: Ligne de l'inventaire | C21: P1 | D21: P2 | E21: P3 | F21: P4 | G21: P5 | H21: Qualification | I21: Fin décl. | J21: Côté | K21: Groupe | L21: L-REC
B22: Sous-ensemble récurrent — E(Pt)
B23: EBITDA périmètre (tel qu'alloué par le vendeur) (cas) | C23: =-'M6 Bridge'!D6 -> -794.95478 | D23: =-'M6 Bridge'!E6 -> -1243.9531 | E23: =-'M6 Bridge'!F6 -> -1297.4922 | F23: =-'M6 Bridge'!G6 -> -1353.124 | G23: =-'M6 Bridge'!H6 -> -1410.926 | H23: récurrent | I23: — | J23: cas | K23: L-M6OTH | L23: —
B24: Allocations vendeur réintégrées (cas) | C24: =-'M6 Bridge'!D7 -> -54.362027 | D24: =-'M6 Bridge'!E7 -> -83.989331 | E24: =-'M6 Bridge'!F7 -> -86.509011 | F24: =-'M6 Bridge'!G7 -> -89.104281 | G24: =-'M6 Bridge'!H7 -> -91.77741 | H24: récurrent | I24: — | J24: cas | K24: L-M6OTH | L24: —
B25: Coûts stand-alone — IT et infrastructure (cas) | C25: =-'M6 Bridge'!D8 -> 10 | D25: =-'M6 Bridge'!E8 -> 28 | E25: =-'M6 Bridge'!F8 -> 40 | F25: =-'M6 Bridge'!G8 -> 40 | G25: =-'M6 Bridge'!H8 -> 40 | H25: récurrent | I25: — | J25: cas | K25: L-M3 | L25: —
B26: Coûts stand-alone — Fonctions support (finance, RH, juridique) (cas) | C26: =-'M6 Bridge'!D9 -> 12 | D26: =-'M6 Bridge'!E9 -> 25.5 | E26: =-'M6 Bridge'!F9 -> 30 | F26: =-'M6 Bridge'!G9 -> 30 | G26: =-'M6 Bridge'!H9 -> 30 | H26: récurrent | I26: — | J26: cas | K26: L-M3 | L26: —
B27: Coûts stand-alone — Distribution et achats (cas) | C27: =-'M6 Bridge'!D10 -> 12.5 | D27: =-'M6 Bridge'!E10 -> 25 | E27: =-'M6 Bridge'!F10 -> 25 | F27: =-'M6 Bridge'!G10 -> 25 | G27: =-'M6 Bridge'!H10 -> 25 | H27: récurrent | I27: — | J27: cas | K27: L-M3 | L27: —
B28: Coûts stand-alone — Qualité, réglementaire, pharmacovigilance (cas) | C28: =-'M6 Bridge'!D11 -> 11.25 | D28: =-'M6 Bridge'!E11 -> 22.5 | E28: =-'M6 Bridge'!F11 -> 25 | F28: =-'M6 Bridge'!G11 -> 25 | G28: =-'M6 Bridge'!H11 -> 25 | H28: récurrent | I28: — | J28: cas | K28: L-M3 | L28: —
B29: Impôts — effet des postes récurrents (cas) | C29: =-'M6 Bridge'!D26 -> 176.7847 | D29: =-'M6 Bridge'!E26 -> 269.92734 | E29: =-'M6 Bridge'!F26 -> 278.08026 | F29: =-'M6 Bridge'!G26 -> 290.89022 | G29: =-'M6 Bridge'!H26 -> 304.19475 | H29: récurrent | I29: — | J29: cas | K29: L-M6OTH | L29: —
B30: Capex courant (cas) | C30: =-'M6 Bridge'!D28 -> 84.940667 | D30: =-'M6 Bridge'!E28 -> 131.23333 | E30: =-'M6 Bridge'!F28 -> 135.17033 | F30: =-'M6 Bridge'!G28 -> 139.22544 | G30: =-'M6 Bridge'!H28 -> 143.4022 | H30: récurrent | I30: — | J30: cas | K30: L-M6OTH | L30: —
B31: BFR courant (cas) | C31: =-'M6 Bridge'!D29 -> 14.844 | D31: =-'M6 Bridge'!E29 -> 22.93398 | E31: =-'M6 Bridge'!F29 -> 23.621999 | F31: =-'M6 Bridge'!G29 -> 24.330659 | G31: =-'M6 Bridge'!H29 -> 25.060579 | H31: récurrent | I31: — | J31: cas | K31: L-M6OTH | L31: —
B32: Autres éléments cash déclarés (cas) | C32: =-'M6 Bridge'!D30 -> 0 | D32: =-'M6 Bridge'!E30 -> 0 | E32: =-'M6 Bridge'!F30 -> 0 | F32: =-'M6 Bridge'!G30 -> 0 | G32: =-'M6 Bridge'!H30 -> 0 | H32: récurrent | I32: — | J32: cas | K32: L-M6OTH | L32: —
B33: EBITDA périmètre (maintien dans le groupe) (contrefactuel) | C33: =+'M7 Financement'!C10 -> 794.95478 | D33: =+'M7 Financement'!D10 -> 1243.9531 | E33: =+'M7 Financement'!E10 -> 1297.4922 | F33: =+'M7 Financement'!F10 -> 1353.124 | G33: =+'M7 Financement'!G10 -> 1410.926 | H33: récurrent | I33: — | J33: contrefactuel | K33: L-CF | L33: —
B34: Impôts (contrefactuel) (contrefactuel) | C34: =+'M7 Financement'!C11 -> -174.89005 | D34: =+'M7 Financement'!D11 -> -273.66969 | E34: =+'M7 Financement'!E11 -> -285.44828 | F34: =+'M7 Financement'!F11 -> -297.68728 | G34: =+'M7 Financement'!G11 -> -310.40372 | H34: récurrent | I34: — | J34: contrefactuel | K34: L-CF | L34: —
B35: Capex courant (contrefactuel) (contrefactuel) | C35: =+'M7 Financement'!C12 -> -84.940667 | D35: =+'M7 Financement'!D12 -> -131.23333 | E35: =+'M7 Financement'!E12 -> -135.17033 | F35: =+'M7 Financement'!F12 -> -139.22544 | G35: =+'M7 Financement'!G12 -> -143.4022 | H35: récurrent | I35: — | J35: contrefactuel | K35: L-CF | L35: —
B36: BFR courant (contrefactuel) (contrefactuel) | C36: =+'M7 Financement'!C13 -> -14.844 | D36: =+'M7 Financement'!D13 -> -22.93398 | E36: =+'M7 Financement'!E13 -> -23.621999 | F36: =+'M7 Financement'!F13 -> -24.330659 | G36: =+'M7 Financement'!G13 -> -25.060579 | H36: récurrent | I36: — | J36: contrefactuel | K36: L-CF | L36: —
B37: Autres éléments cash déclarés (contrefactuel) (contrefactuel) | C37: =+'M7 Financement'!C14 -> 0 | D37: =+'M7 Financement'!D14 -> 0 | E37: =+'M7 Financement'!E14 -> 0 | F37: =+'M7 Financement'!F14 -> 0 | G37: =+'M7 Financement'!G14 -> 0 | H37: récurrent | I37: — | J37: contrefactuel | K37: L-CF | L37: —
B38: E(Pt) — écart récurrent (R-EGAP) | C38: =SUM(C23:C37) -> -6.7173808 | D38: =SUM(D23:D37) -> 13.268322 | E38: =SUM(E23:E37) -> 26.122971 | F38: =SUM(F23:F37) -> 24.09866 | G38: =SUM(G23:G37) -> 22.01362
B40: Sous-ensemble ponctuel — N(Pt)
B41: TSA — IT (ERP, infrastructure, support) (cas) | C41: =-'M6 Bridge'!D12 -> 16.8 | D41: =-'M6 Bridge'!E12 -> 25.2 | E41: =-'M6 Bridge'!F12 -> 8.4 | F41: =-'M6 Bridge'!G12 -> 0 | G41: =-'M6 Bridge'!H12 -> 0 | H41: ponctuel | I41: P3 | J41: cas | K41: L-M4 | L41: —
B42: TSA — Supply chain et logistique (cas) | C42: =-'M6 Bridge'!D13 -> 10 | D42: =-'M6 Bridge'!E13 -> 12.5 | E42: =-'M6 Bridge'!F13 -> 0 | F42: =-'M6 Bridge'!G13 -> 0 | G42: =-'M6 Bridge'!H13 -> 0 | H42: ponctuel | I42: P2 | J42: cas | K42: L-M4 | L42: —
B43: TSA — Finance (comptabilité, paie, fiscalité) (cas) | C43: =-'M6 Bridge'!D14 -> 6.8 | D43: =-'M6 Bridge'!E14 -> 3.4 | E43: =-'M6 Bridge'!F14 -> 0 | F43: =-'M6 Bridge'!G14 -> 0 | G43: =-'M6 Bridge'!H14 -> 0 | H43: ponctuel | I43: P2 | J43: cas | K43: L-M4 | L43: —
B44: TSA — Réglementaire et pharmacovigilance (cas) | C44: =-'M6 Bridge'!D15 -> 4 | D44: =-'M6 Bridge'!E15 -> 6 | E44: =-'M6 Bridge'!F15 -> 2 | F44: =-'M6 Bridge'!G15 -> 0 | G44: =-'M6 Bridge'!H15 -> 0 | H44: ponctuel | I44: P3 | J44: cas | K44: L-M4 | L44: —
B45: TSA — Autres (immobilier, achats) (cas) | C45: =-'M6 Bridge'!D16 -> 2.4 | D45: =-'M6 Bridge'!E16 -> 1.2 | E45: =-'M6 Bridge'!F16 -> 0 | F45: =-'M6 Bridge'!G16 -> 0 | G45: =-'M6 Bridge'!H16 -> 0 | H45: ponctuel | I45: P2 | J45: cas | K45: L-M4 | L45: —
B46: One-off — Séparation IT (migration ERP, données, réseaux) (cas) | C46: =-'M6 Bridge'!D17 -> 24 | D46: =-'M6 Bridge'!E17 -> 34 | E46: =-'M6 Bridge'!F17 -> 0 | F46: =-'M6 Bridge'!G17 -> 0 | G46: =-'M6 Bridge'!H17 -> 0 | H46: ponctuel | I46: P2 | J46: cas | K46: L-M5 | L46: —
B47: One-off — Mise en place des entités juridiques (cas) | C47: =-'M6 Bridge'!D18 -> 12 | D47: =-'M6 Bridge'!E18 -> 6 | E47: =-'M6 Bridge'!F18 -> 0 | F47: =-'M6 Bridge'!G18 -> 0 | G47: =-'M6 Bridge'!H18 -> 0 | H47: ponctuel | I47: P2 | J47: cas | K47: L-M5 | L47: —
B48: One-off — Marque et packaging (rebranding) (cas) | C48: =-'M6 Bridge'!D19 -> 14 | D48: =-'M6 Bridge'!E19 -> 16 | E48: =-'M6 Bridge'!F19 -> 4 | F48: =-'M6 Bridge'!G19 -> 0 | G48: =-'M6 Bridge'!H19 -> 0 | H48: ponctuel | I48: P3 | J48: cas | K48: L-M5 | L48: —
...

Sheet Contrôles
B2: RELATIONS CONTRÔLÉES (§5.2)
B3: Les tolérances sont déclarées dans opella_integration_manifest.json, jamais ici. Une comparaison symbolique déclare la tolérance « exact ».
B5: Id | C5: Énoncé contrôlé | D5: Écart mesuré | E5: Propriétaire
B6: R-PERIM | C6: EBITDA périmètre P0 = CA P0 × marge périmètre P0 | D6: =Hypothèses!C9-Hypothèses!C6*Hypothèses!C8 -> 0 | E6: G1
B7: R-MULT | C7: Multiple d'entrée implicite = EV ÷ EBITDA périmètre P0 | D7: =Hypothèses!C11-Hypothèses!C10/Hypothèses!C9 -> 0 | E7: G1
B8: R-OWN | C8: Somme des participations = 100 % | D8: =Hypothèses!C15-1 -> 0 | E8: G1
B9: R-STANDALONE | C9: EBITDA stand-alone run-rate = EBITDA périmètre + allocations réintégrées + total M3 | D9: ='M6 Bridge'!C33-('M6 Bridge'!H6+'M6 Bridge'!H7+'M3 Stand-alone'!C15) -> 0 | E9: G1
B10: R-RAMP | C10: Coût appliqué = run-rate × montée en charge, taux borné à [0 ; 1] | D10: =MAX(0,'M3 Stand-alone'!E11/'M3 Stand-alone'!C11-1)+MAX(0,-('M3 Stand-alone'!E11/'M3 Stand-alone'!C11))+MAX(0,'M3 Stand-alone'!F11/'M3 Stand-alone'!C11-1)+MAX(0,-('M3 Stand-alone'!F11/'M3 Stand-alone'!C11))+MAX(0,'M3 Stand-alone'!G11/'M3 Stand-alone'!C11-1)+MAX(0,-('M3 Stand-alone'!G11/'M3 Stand-alone'!C11))+MAX(0,'M3 Stand-alone'!H11/'M3 Stand-alone'!C11-1)+MAX(0,-('M3 Stand-alone'!H11/'M3 Stand-alone'!C11))+MAX(0,'M3 Stand-alone'!I11/'M3 Stand-alone'!C11-1)+MAX(0,-('M3 Stand-alone'!I11/'M3 Stand-alone'!C11))+MAX(0,'M3 Stand-alone'!E12/'M3 Stand-alone'!C12-1)+MAX(0,-('M3 Stand-alone'!E12/'M3 Stand-alone'!C12))+MAX(0,'M3 Stand-alone'!F12/'M3 Stand-alone'!C12-1)+MAX(0,-('M3 Stand-alone'!F12/'M3 Stand-alone'!C12))+MAX(0,'M3 Stand-alone'!G12/'M3 Stand-alone'!C12-1)+MAX(0,-('M3 Stand-alone'!G12/'M3 Stand-alone'!C12))+MAX(0,'M3 Stand-alone'!H12/'M3 Stand-alone'!C12-1)+MAX(0,-('M3 Stand-alone'!H12/'M3 Stand-alone'!C12))+MAX(0,'M3 Stand-alone'!I12/'M3 Stand-alone'!C12-1)+MAX(0,-('M3 Stand-alone'!I12/'M3 Stand-alone'!C12))+MAX(0,'M3 Stand-alone'!E13/'M3 Stand-alone'!C13-1)+MAX(0,-('M3 Stand-alone'!E13/'M3 Stand-alone'!C13))+MAX(0,'M3 Stand-alone'!F13/'M3 Stand-alone'!C13-1)+MAX(0,-('M3 Stand-alone'!F13/'M3 Stand-alone'!C13))+MAX(0,'M3 Stand-alone'!G13/'M3 Stand-alone'!C13-1)+MAX(0,-('M3 Stand-alone'!G13/'M3 Stand-alone'!C13))+MAX(0,'M3 Stand-alone'!H13/'M3 Stand-alone'!C13-1)+MAX(0,-('M3 Stand-alone'!H13/'M3 Stand-alone'!C13))+MAX(0,'M3 Stand-alone'!I13/'M3 Stand-alone'!C13-1)+MAX(0,-('M3 Stand-alone'!I13/'M3 Stand-alone'!C13))+MAX(0,'M3 Stand-alone'!E14/'M3 Stand-alone'!C14-1)+MAX(0,-('M3 Stand-alone'!E14/'M3 Stand-alone'!C14))+MAX(0,'M3 Stand-alone'!F14/'M3 Stand-alone'!C14-1)+MAX(0,-('M3 Stand-alone'!F14/'M3 Stand-alone'!C14))+MAX(0,'M3 Stand-alone'!G14/'M3 Stand-alone'!C14-1)+MAX(0,-('M3 Stand-alone'!G14/'M3 Stand-alone'!C14))+MAX(0,'M3 Stand-alone'!H14/'M3 Stand-alone'!C14-1)+MAX(0,-('M3 Stand-alone'!H14/'M3 Stand-alone'!C14))+MAX(0,'M3 Stand-alone'!I14/'M3 Stand-alone'!C14-1)+MAX(0,-('M3 Stand-alone'!I14/'M3 Stand-alone'!C14)) -> 0 | E10: G1
B11: R-TSA-SUM | C11: Total TSA d'une période = somme des services de M4 | D11: =('M4 TSA'!J11-('M4 TSA'!J6+'M4 TSA'!J7+'M4 TSA'!J8+'M4 TSA'!J9+'M4 TSA'!J10))+('M4 TSA'!K11-('M4 TSA'!K6+'M4 TSA'!K7+'M4 TSA'!K8+'M4 TSA'!K9+'M4 TSA'!K10))+('M4 TSA'!L11-('M4 TSA'!L6+'M4 TSA'!L7+'M4 TSA'!L8+'M4 TSA'!L9+'M4 TSA'!L10))+('M4 TSA'!M11-('M4 TSA'!M6+'M4 TSA'!M7+'M4 TSA'!M8+'M4 TSA'!M9+'M4 TSA'!M10))+('M4 TSA'!N11-('M4 TSA'!N6+'M4 TSA'!N7+'M4 TSA'!N8+'M4 TSA'!N9+'M4 TSA'!N10)) -> 0 | E11: G1
B12: R-TSA-CAL | C12: Somme des mois affectés = durée contractuelle du service | D12: =SUM(Calendrier!J19:J23) -> 0 | E12: G1
B13: R-DOUBLERUN | C13: Fenêtre de double run ≥ 0 et incluse dans la durée du service | D13: =MAX(0,-'M4 TSA'!H6)+MAX(0,'M4 TSA'!H6-'M4 TSA'!E6)+MAX(0,-'M4 TSA'!H7)+MAX(0,'M4 TSA'!H7-'M4 TSA'!E7)+MAX(0,-'M4 TSA'!H8)+MAX(0,'M4 TSA'!H8-'M4 TSA'!E8)+MAX(0,-'M4 TSA'!H9)+MAX(0,'M4 TSA'!H9-'M4 TSA'!E9)+MAX(0,-'M4 TSA'!H10)+MAX(0,'M4 TSA'!H10-'M4 TSA'!E10) -> 0 | E13: G1
B14: R-ONEOFF-SUM | C14: Total one-offs = somme des lignes de M5 | D14: =('M5 One-offs'!D12-('M5 One-offs'!D6+'M5 One-offs'!D7+'M5 One-offs'!D8+'M5 One-offs'!D9+'M5 One-offs'!D10+'M5 One-offs'!D11))+('M5 One-offs'!E12-('M5 One-offs'!E6+'M5 One-offs'!E7+'M5 One-offs'!E8+'M5 One-offs'!E9+'M5 One-offs'!E10+'M5 One-offs'!E11))+('M5 One-offs'!F12-('M5 One-offs'!F6+'M5 One-offs'!F7+'M5 One-offs'!F8+'M5 One-offs'!F9+'M5 One-offs'!F10+'M5 One-offs'!F11))+('M5 One-offs'!G12-('M5 One-offs'!G6+'M5 One-offs'!G7+'M5 One-offs'!G8+'M5 One-offs'!G9+'M5 One-offs'!G10+'M5 One-offs'!G11))+('M5 One-offs'!H12-('M5 One-offs'!H6+'M5 One-offs'!H7+'M5 One-offs'!H8+'M5 One-offs'!H9+'M5 One-offs'!H10+'M5 One-offs'!H11)) -> 0 | E14: G1
B15: R-CASH | C15: Cash de période = somme signée des lignes du bridge M6 | D15: =('M6 Bridge'!D31-('M6 Bridge'!D6+'M6 Bridge'!D7+'M6 Bridge'!D8+'M6 Bridge'!D9+'M6 Bridge'!D10+'M6 Bridge'!D11+'M6 Bridge'!D12+'M6 Bridge'!D13+'M6 Bridge'!D14+'M6 Bridge'!D15+'M6 Bridge'!D16+'M6 Bridge'!D17+'M6 Bridge'!D18+'M6 Bridge'!D19+'M6 Bridge'!D20+'M6 Bridge'!D21+'M6 Bridge'!D22+'M6 Bridge'!D23+'M6 Bridge'!D24+'M6 Bridge'!D25+'M6 Bridge'!D26+'M6 Bridge'!D27+'M6 Bridge'!D28+'M6 Bridge'!D29+'M6 Bridge'!D30))+('M6 Bridge'!E31-('M6 Bridge'!E6+'M6 Bridge'!E7+'M6 Bridge'!E8+'M6 Bridge'!E9+'M6 Bridge'!E10+'M6 Bridge'!E11+'M6 Bridge'!E12+'M6 Bridge'!E13+'M6 Bridge'!E14+'M6 Bridge'!E15+'M6 Bridge'!E16+'M6 Bridge'!E17+'M6 Bridge'!E18+'M6 Bridge'!E19+'M6 Bridge'!E20+'M6 Bridge'!E21+'M6 Bridge'!E22+'M6 Bridge'!E23+'M6 Bridge'!E24+'M6 Bridge'!E25+'M6 Bridge'!E26+'M6 Bridge'!E27+'M6 Bridge'!E28+'M6 Bridge'!E29+'M6 Bridge'!E30))+('M6 Bridge'!F31-('M6 Bridge'!F6+'M6 Bridge'!F7+'M6 Bridge'!F8+'M6 Bridge'!F9+'M6 Bridge'!F10+'M6 Bridge'!F11+'M6 Bridge'!F12+'M6 Bridge'!F13+'M6 Bridge'!F14+'M6 Bridge'!F15+'M6 Bridge'!F16+'M6 Bridge'!F17+'M6 Bridge'!F18+'M6 Bridge'!F19+'M6 Bridge'!F20+'M6 Bridge'!F21+'M6 Bridge'!F22+'M6 Bridge'!F23+'M6 Bridge'!F24+'M6 Bridge'!F25+'M6 Bridge'!F26+'M6 Bridge'!F27+'M6 Bridge'!F28+'M6 Bridge'!F29+'M6 Bridge'!F30))+('M6 Bridge'!G31-('M6 Bridge'!G6+'M6 Bridge'!G7+'M6 Bridge'!G8+'M6 Bridge'!G9+'M6 Bridge'!G10+'M6 Bridge'!G11+'M6 Bridge'!G12+'M6 Bridge'!G13+'M6 Bridge'!G14+'M6 Bridge'!G15+'M6 Bridge'!G16+'M6 Bridge'!G17+'M6 Bridge'!G18+'M6 Bridge'!G19+'M6 Bridge'!G20+'M6 Bridge'!G21+'M6 Bridge'!G22+'M6 Bridge'!G23+'M6 Bridge'!G24+'M6 Bridge'!G25+'M6 Bridge'!G26+'M6 Bridge'!G27+'M6 Bridge'!G28+'M6 Bridge'!G29+'M6 Bridge'!G30))+('M6 Bridge'!H31-('M6 Bridge'!H6+'M6 Bridge'!H7+'M6 Bridge'!H8+'M6 Bridge'!H9+'M6 Bridge'!H10+'M6 Bridge'!H11+'M6 Bridge'!H12+'M6 Bridge'!H13+'M6 Bridge'!H14+'M6 Bridge'!H15+'M6 Bridge'!H16+'M6 Bridge'!H17+'M6 Bridge'!H18+'M6 Bridge'!H19+'M6 Bridge'!H20+'M6 Bridge'!H21+'M6 Bridge'!H22+'M6 Bridge'!H23+'M6 Bridge'!H24+'M6 Bridge'!H25+'M6 Bridge'!H26+'M6 Bridge'!H27+'M6 Bridge'!H28+'M6 Bridge'!H29+'M6 Bridge'!H30)) -> 0 | E15: G1
B16: R-CF | C16: Contrefactuel unique et ligné : son cash = somme de ses lignes | D16: =('M7 Financement'!C15-('M7 Financement'!C10+'M7 Financement'!C11+'M7 Financement'!C12+'M7 Financement'!C13+'M7 Financement'!C14))+('M7 Financement'!D15-('M7 Financement'!D10+'M7 Financement'!D11+'M7 Financement'!D12+'M7 Financement'!D13+'M7 Financement'!D14))+('M7 Financement'!E15-('M7 Financement'!E10+'M7 Financement'!E11+'M7 Financement'!E12+'M7 Financement'!E13+'M7 Financement'!E14))+('M7 Financement'!F15-('M7 Financement'!F10+'M7 Financement'!F11+'M7 Financement'!F12+'M7 Financement'!F13+'M7 Financement'!F14))+('M7 Financement'!G15-('M7 Financement'!G10+'M7 Financement'!G11+'M7 Financement'!G12+'M7 Financement'!G13+'M7 Financement'!G14)) -> 0 | E16: G1
B17: R-FUNDING-CUM | C17: s = −c ; S cumulé depuis 0 ; B = MAX(0 ; S), écrêtage appliqué une seule fois au cumul | D17: =('M7 Financement'!C62+'M7 Financement'!C61)+('M7 Financement'!D62+'M7 Financement'!D61)+('M7 Financement'!E62+'M7 Financement'!E61)+('M7 Financement'!F62+'M7 Financement'!F61)+('M7 Financement'!G62+'M7 Financement'!G61)+('M7 Financement'!C63-0-'M7 Financement'!C62)+('M7 Financement'!C64-MAX(0,'M7 Financement'!C63))+('M7 Financement'!D63-'M7 Financement'!C63-'M7 Financement'!D62)+('M7 Financement'!D64-MAX(0,'M7 Financement'!D63))+('M7 Financement'!E63-'M7 Financement'!D63-'M7 Financement'!E62)+('M7 Financement'!E64-MAX(0,'M7 Financement'!E63))+('M7 Financement'!F63-'M7 Financement'!E63-'M7 Financement'!F62)+('M7 Financement'!F64-MAX(0,'M7 Financement'!F63))+('M7 Financement'!G63-'M7 Financement'!F63-'M7 Financement'!G62)+('M7 Financement'!G64-MAX(0,'M7 Financement'!G63)) -> 0 | E17: G2
B18: R-PEAK | C18: Aucun B négatif ; pic = MAX(B) ; date = première période atteignant ce maximum | D18: =MAX(0,-'M7 Financement'!C64)+MAX(0,-'M7 Financement'!D64)+MAX(0,-'M7 Financement'!E64)+MAX(0,-'M7 Financement'!F64)+MAX(0,-'M7 Financement'!G64)+('M7 Financement'!C71-MAX('M7 Financement'!C64:G64)) -> 0 | E18: G2
B19: R-MONO | C19: Toute période de flux négatif s'explique par des lignes déclarées à contribution négative, sans résidu | D19: symbolique | E19: G2
B20: R-QUAL | C20: Qualification unique, cohérente avec le module d'origine, l'empreinte de période et la fin déclarée | D20: symbolique | E20: G1
B21: R-EGAP | C21: E(Pt) = somme ascendante des contributions des lignes récurrentes, jamais un résidu de s | D21: symbolique | E21: G2
B22: R-NPONC | C22: N(Pt) = somme ascendante des contributions des lignes ponctuelles, jamais un résidu de s | D22: symbolique | E22: G2
B23: R-RECUR | C23: s(Pt) = E(Pt) + N(Pt) sur chaque période de l'horizon | D23: =SUM('M7 Financement'!C67:G67) -> 1.7097435e-13 | E23: G2
B24: R-RESORB | C24: État de sortie de pic selon la table de décision du §6.1.1 sur le niveau B_H et le signe de E_H | D24: symbolique | E24: G2
B25: R-PK | C25: Pk = plus petite période de la fenêtre finale de son état ; absent des deux autres états | D25: symbolique | E25: G2
B26: R-STEADY | C26: Date de régime établi = première période satisfaisant la règle 3 du §4 | D26: symbolique | E26: G2
B27: R-SEPCOST | C27: O-SEPCOST = TSA + one-offs + capex de séparation, hors BFR de séparation | D27: ='M6 Bridge'!C34+('M4 TSA'!J11+'M5 One-offs'!D12+'M6 Bridge'!D23+'M4 TSA'!K11+'M5 One-offs'!E12+'M6 Bridge'!E23+'M4 TSA'!L11+'M5 One-offs'!F12+'M6 Bridge'!F23+'M4 TSA'!M11+'M5 One-offs'!G12+'M6 Bridge'!G23+'M4 TSA'!N11+'M5 One-offs'!H12+'M6 Bridge'!H23) -> 0 | E27: G2

Sheet Scénarios
B2: SCÉNARIOS — QUATRE LEVIERS INDÉPENDANTS (§7)
B3: Valeurs recalculées par la même logique que le cas central : aucun tableau statique. Les états sont nommés basse, centrale et haute ; l'état par défaut est le cas central, atteignable sans interaction.
B5: Levier | C5: État | D5: O-RUNRATE | E5: O-SEPCOST | F5: O-PEAK | G5: Date du pic | H5: O-STEADY
B6: Coûts stand-alone récurrents | C6: basse | D6: 78 | E6: 295.7 | F6: 253.46219 | G6: P2 | H6: P4
C7: centrale | D7: 120 | E7: 295.7 | F7: 323.21991 | G7: P3 | H7: P4
C8: haute | D8: 156 | E8: 295.7 | F8: 437.91169 | G8: P5 | H8: P4
B10: Retard de sortie de TSA | C10: basse | D10: 120 | E10: 280.7 | F10: 311.51991 | G10: P3 | H10: P4
C11: centrale | D11: 120 | E11: 295.7 | F11: 323.21991 | G11: P3 | H11: P4
C12: haute | D12: 120 | E12: 349.7 | F12: 381.31822 | G12: P6 | H12: P5
B14: One-offs | C14: basse | D14: 120 | E14: 257.7 | F14: 293.57991 | G14: P3 | H14: P4
C15: centrale | D15: 120 | E15: 295.7 | F15: 323.21991 | G15: P3 | H15: P4
C16: haute | D16: 120 | E16: 364.1 | F16: 376.57191 | G16: P3 | H16: P4
B18: Croissance et marge | C18: basse | D18: 120 | E18: 295.7 | F18: 338.45823 | G18: P5 | H18: P4
C19: centrale | D19: 120 | E19: 295.7 | F19: 323.21991 | G19: P3 | H19: P4
C20: haute | D20: 120 | E20: 295.7 | F20: 315.8202 | G20: P3 | H20: P4

Sheet M8 Acquéreur
B2: M8 — IMPLICATIONS ACQUÉREUR (ENCADRÉ SECONDAIRE, ILLUSTRATIF)
B3: Cette lecture secondaire présente cinq valeurs numériques, toutes issues de la même chaîne de chiffres que le cœur du cas. Elle ne calcule aucun retour sponsor : ni multiple de sortie, ni taux de rendement, ni grille de sensibilité de sortie.
B5: Levier d'entrée retenu (x EBITDA stand-alone) | C5: 4 | D5: hypothèse « e » de financement large-cap
B6: EBITDA stand-alone en run-rate (M€) | C6: ='M6 Bridge'!C33 -> 1382.7034
B7: Dette d'acquisition implicite (M€) | C7: ='M8 Acquéreur'!C5*'M8 Acquéreur'!C6 -> 5530.8136
B8: Chèque d'equity à l'entrée (M€) | C8: =Hypothèses!C10-'M8 Acquéreur'!C7 -> 10469.186
B10: Sensibilité sommaire : effet d'un pic de besoin non financé | C10: ='M7 Financement'!C71 -> 323.21991 | D10: le pic de besoin de séparation s'ajoute au chèque d'equity s'il n'est pas couvert par une ligne dédiée ; il n'est pas une dette d'acquisition
